Workbook
Name TargetPace: Parameters!$B$7
Name TargetTime: Parameters!$B$5
Name MaxHR: Parameters!$B$23
Name RestingHR: Parameters!$B$24
Name RecoveryPace: Parameters!$B$35
Name EasyPace: Parameters!$B$36
Name TempoPace: Parameters!$B$37
Name IntervalPace: Parameters!$B$38
Name DailyCalories: Parameters!$B$47
Name HydrationGoal: Parameters!$B$50

Sheet Parameters
A1: 5K Training Parameters
A3: Parameter | B3: Value | C3: Unit | D3: Notes
A4: RACE GOALS
A5: Target Finish Time | B5: 30 | C5: min | D5: Your goal 5K time
A6: Race Distance | B6: 5 | C6: km | D6: Standard 5K
A7: Target Pace | B7: =B5/B6 | C7: min/km | D7: Calculated from finish time
A8: Race Date | B8: 2026-04-15 | D8: Your target race date
A9: Training Start Date | B9: 2026-01-20 | D9: When you began training
A11: TRAINING SCHEDULE
A12: Training Weeks | B12: 12 | C12: weeks | D12: Total program duration
A13: Weekly Workout Frequency | B13: 4 | C13: days | D13: Target workouts per week
A14: Long Run Day | B14: Sunday | D14: Preferred day for long runs
A15: Rest Days Per Week | B15: 2 | C15: days | D15: Required recovery days
A16: Cross-Training Days | B16: 1 | C16: days | D16: Non-running activity days
A17: Taper Weeks | B17: 2 | C17: weeks | D17: Reduced volume before race
A19: FITNESS PROFILE
A20: Current Fitness Level | B20: Beginner | D20: Beginner/Intermediate/Advanced
A21: Max Heart Rate | B21: 185 | C21: bpm | D21: 220 - age (or tested)
A22: Resting Heart Rate | B22: 65 | C22: bpm | D22: Measured in morning
A23: Starting Weight | B23: 75 | C23: kg | D23: Weight at training start
A24: Target Weight | B24: 72 | C24: kg | D24: Goal weight by race day
A25: Starting Body Fat % | B25: 22 | C25: % | D25: If known
A27: PACE ZONES (min/km)
A28: Recovery Pace | B28: =B7+1.5 | C28: min/km | D28: Very easy, conversational
A29: Easy Pace | B29: =B7+1 | C29: min/km | D29: Comfortable aerobic
A30: Tempo Pace | B30: =B7 | C30: min/km | D30: Race pace effort
A31: Interval Pace | B31: =B7-0.5 | C31: min/km | D31: Fast, controlled
A32: Sprint Pace | B32: =B7-1 | C32: min/km | D32: Maximum effort
A34: HEART RATE ZONES (bpm)
A35: HR Zone 1 (Recovery) | B35: =B23*0.6 | C35: bpm | D35: 50-60% max HR
A36: HR Zone 2 (Easy) | B36: =B23*0.7 | C36: bpm | D36: 60-70% max HR
A37: HR Zone 3 (Aerobic) | B37: =B23*0.8 | C37: bpm | D37: 70-80% max HR
A38: HR Zone 4 (Threshold) | B38: =B23*0.9 | C38: bpm | D38: 80-90% max HR
A39: HR Zone 5 (Max) | B39: =B23*0.95 | C39: bpm | D39: 90-100% max HR
A41: NUTRITION TARGETS
A42: Daily Calories | B42: 2200 | C42: kcal | D42: Target daily intake
A43: Protein Target | B43: 120 | C43: g | D43: For muscle recovery
A44: Carb Target | B44: 250 | C44: g | D44: Fuel for runs
A45: Daily Hydration | B45: 3 | C45: L | D45: Water intake goal
A46: Pre-Run Meal (hrs before) | B46: 2 | C46: hrs | D46: Eating window before run

Sheet Workout Log
A1: Workout Log - Raw Data Entry (3 Months)
A3: Date | B3: Week | C3: Day | D3: Workout Type | E3: Distance (km) | F3: Time (min) | G3: Avg HR (bpm) | H3: Max HR (bpm) | I3: RPE (1-10) | J3: Weather | K3: Temp (C) | L3: Terrain | M3: Elevation (m) | N3: Calories Burned | O3: Warm-up (min) | P3: Cool-down (min) | Q3: Stretching (min) | R3: Sleep Last Night (hrs) | S3: Resting HR (bpm) | T3: Weight (kg) | U3: Hydration (L) | V3: Calories Eaten | W3: Protein (g) | X3: Notes
A4: 2026-01-21 | B4: 1 | C4: 3 | D4: Tempo | E4: 4.2 | F4: 27 | G4: 156 | H4: 167 | I4: 8 | J4: Sunny | K4: 5 | L4: Flat | M4: 11 | N4: 354 | O4: 6 | P4: 9 | Q4: 14 | R4: 6.1 | S4: 62 | T4: 75.2 | U4: 3.1 | V4: 2329 | W4: 104 | X4: Hot day
A5: 2026-01-22 | B5: 1 | C5: 4 | D5: Cross-Train | E5: 0 | F5: 35 | G5: 138 | H5: 148 | I5: 4 | J5: Windy | K5: 8 | L5: Trail | M5: 108 | N5: 210 | O5: 9 | P5: 7 | Q5: 5 | R5: 8.2 | S5: 65 | T5: 74.6 | U5: 3.4 | V5: 1980 | W5: 125 | X5: New route
A6: 2026-01-24 | B6: 1 | C6: 6 | D6: Easy | E6: 4.2 | F6: 33 | G6: 142 | H6: 151 | I6: 3 | J6: Sunny | K6: 17 | L6: Trail | M6: 136 | N6: 372 | O6: 10 | P6: 7 | Q6: 7 | R6: 7.1 | S6: 62 | T6: 75.1 | U6: 3.1 | V6: 1973 | W6: 128 | X6: Good pace
A7: 2026-01-25 | B7: 1 | C7: 7 | D7: Long | E7: 5 | F7: 38 | G7: 144 | H7: 155 | I7: 5 | J7: Windy | K7: 13 | L7: Flat | M7: 11 | N7: 439 | O7: 9 | P7: 10 | Q7: 10 | R7: 6.6 | S7: 64 | T7: 74.8 | U7: 3.4 | V7: 2369 | W7: 99 | X7: Steady throughout
A8: 2026-01-28 | B8: 2 | C8: 3 | D8: Intervals | E8: 4.2 | F8: 27 | G8: 176 | H8: 196 | I8: 8 | J8: Sunny | K8: 9 | L8: Mixed | M8: 10 | N8: 354 | O8: 10 | P8: 8 | Q8: 14 | R8: 6.2 | S8: 64 | T8: 74.9 | U8: 2.7 | V8: 2157 | W8: 125 | X8: Felt strong
A9: 2026-01-29 | B9: 2 | C9: 4 | D9: Cross-Train | E9: 0 | F9: 38 | G9: 145 | H9: 155 | I9: 4 | J9: Hot | K9: 30 | L9: Treadmill | M9: 29 | N9: 228 | O9: 6 | P9: 9 | Q9: 6 | R9: 8.6 | S9: 63 | T9: 75.1 | U9: 2.8 | V9: 2103 | W9: 99 | X9: Hill repeats
A10: 2026-01-31 | B10: 2 | C10: 6 | D10: Easy | E10: 4.1 | F10: 32 | G10: 152 | H10: 160 | I10: 5 | J10: Rainy | K10: 12 | L10: Flat | M10: 12 | N10: 362 | O10: 9 | P10: 5 | Q10: 6 | R10: 8.2 | S10: 67 | T10: 74.3 | U10: 3.1 | V10: 2028 | W10: 98 | X10: Cold morning
A11: 2026-02-01 | B11: 2 | C11: 7 | D11: Long | E11: 5.3 | F11: 40 | G11: 149 | H11: 160 | I11: 7 | J11: Windy | K11: 25 | L11: Trail | M11: 132 | N11: 464 | O11: 9 | P11: 8 | Q11: 6 | R11: 6.7 | S11: 61 | T11: 74.6 | U11: 2.9 | V11: 2135 | W11: 127 | X11: Strong finish
A12: 2026-02-04 | B12: 3 | C12: 3 | D12: Tempo | E12: 3.7 | F12: 25 | G12: 166 | H12: 181 | I12: 6 | J12: Cloudy | K12: 22 | L12: Hilly | M12: 141 | N12: 315 | O12: 6 | P12: 8 | Q12: 11 | R12: 6.6 | S12: 61 | T12: 74.8 | U12: 2.5 | V12: 2320 | W12: 119 | X12: Tired legs
A13: 2026-02-05 | B13: 3 | C13: 4 | D13: Cross-Train | E13: 0 | F13: 31 | G13: 137 | H13: 147 | I13: 5 | J13: Cloudy | K13: 18 | L13: Hilly | M13: 91 | N13: 186 | O13: 8 | P13: 6 | Q13: 6 | R13: 7.3 | S13: 67 | T13: 75 | U13: 2.1 | V13: 2453 | W13: 90 | X13: Great weather
A14: 2026-02-07 | B14: 3 | C14: 6 | D14: Easy | E14: 4.7 | F14: 35 | G14: 150 | H14: 165 | I14: 3 | J14: Windy | K14: 13 | L14: Track | M14: 14 | N14: 410 | O14: 8 | P14: 10 | Q14: 13 | R14: 8 | S14: 64 | T14: 74.3 | U14: 2.4 | V14: 1959 | W14: 127 | X14: Perfect conditions
A15: 2026-02-09 | B15: 3 | C15: 1 | D15: Easy | E15: 3.1 | F15: 23 | G15: 151 | H15: 161 | I15: 3 | J15: Sunny | K15: 12 | L15: Track | M15: 8 | N15: 270 | O15: 9 | P15: 6 | Q15: 14 | R15: 7.8 | S15: 65 | T15: 74.1 | U15: 3 | V15: 2478 | W15: 123 | X15: Track session
... A35: 2026-03-14 | B35: 8 | C35: 6 | D35: Easy | E35: 4.5 | F35: 35 | G35: 138 | H35: 149 | I35: 3 | J35: Cold | K35: 7 | L35: Trail | M35: 45 | N35: 397 | O35: 6 | P35: 7 | Q35: 8 | R35: 7.1 | S35: 62 | T35: 73.3 | U35: 2.8 | V35: 2180 | W35: 92 | X35: Tired legs
A36: 2026-03-15 | B36: 8 | C36: 7 | D36: Long | E36: 7.6 | F36: 55 | G36: 148 | H36: 157 | I36: 6 | J36: Rainy | K36: 10 | L36: Flat | M36: 13 | N36: 659 | O36: 8 | P36: 5 | Q36: 6 | R36: 7.2 | S36: 60 | T36: 73.9 | U36: 3 | V36: 2055 | W36: 99
A37: 2026-03-16 | B37: 8 | C37: 1 | D37: Easy | E37: 3.2 | F37: 24 | G37: 146 | H37: 157 | I37: 5 | J37: Windy | K37: 14 | L37: Treadmill | M37: 24 | N37: 280 | O37: 5 | P37: 9 | Q37: 6 | R37: 8.8 | S37: 61 | T37: 73.9 | U37: 2.4 | V37: 1983 | W37: 100 | X37: Strong finish
A38: 2026-03-18 | B38: 9 | C38: 3 | D38: Tempo | E38: 3.7 | F38: 23 | G38: 161 | H38: 178 | I38: 6 | J38: Hot | K38: 33 | L38: Flat | M38: 26 | N38: 309 | O38: 6 | P38: 7 | Q38: 15 | R38: 7.8 | S38: 66 | T38: 74.2 | U38: 2.6 | V38: 2457 | W38: 104 | X38: Easy effort
A39: 2026-03-19 | B39: 9 | C39: 4 | D39: Cross-Train | E39: 0 | F39: 32 | G39: 126 | H39: 133 | I39: 5 | J39: Sunny | K39: 19 | L39: Mixed | M39: 14 | N39: 192 | O39: 10 | P39: 8 | Q39: 9 | R39: 7.5 | S39: 63 | T39: 73.6 | U39: 2.9 | V39: 2342 | W39: 137 | X39: Track session
A40: 2026-03-21 | B40: 9 | C40: 6 | D40: Easy | E40: 3.1 | F40: 23 | G40: 133 | H40: 145 | I40: 5 | J40: Windy | K40: 13 | L40: Hilly | M40: 131 | N40: 270 | O40: 10 | P40: 8 | Q40: 6 | R40: 7.4 | S40: 63 | T40: 73.5 | U40: 3 | V40: 2064 | W40: 111 | X40: PR attempt
A41: 2026-03-22 | B41: 9 | C41: 7 | D41: Long | E41: 7.5 | F41: 58 | G41: 133 | H41: 148 | I41: 5 | J41: Cold | K41: -2 | L41: Mixed | M41: 22 | N41: 661 | O41: 8 | P41: 8 | Q41: 5 | R41: 6.6 | S41: 61 | T41: 73.8 | U41: 2.7 | V41: 2352 | W41: 138 | X41: Tired legs
A42: 2026-03-23 | B42: 9 | C42: 1 | D42: Easy | E42: 4.1 | F42: 32 | G42: 146 | H42: 161 | I42: 3 | J42: Cloudy | K42: 14 | L42: Treadmill | M42: 5 | N42: 362 | O42: 9 | P42: 8 | Q42: 6 | R42: 6.7 | S42: 65 | T42: 74 | U42: 2.7 | V42: 2020 | W42: 131 | X42: Easy effort
A43: 2026-03-25 | B43: 10 | C43: 3 | D43: Intervals | E43: 4 | F43: 25 | G43: 173 | H43: 195 | I43: 7 | J43: Cold | K43: 6 | L43: Mixed | M43: 9 | N43: 335 | O43: 5 | P43: 7 | Q43: 11 | R43: 7 | S43: 65 | T43: 73.6 | U43: 3.2 | V43: 2189 | W43: 136 | X43: New route
A44: 2026-03-26 | B44: 10 | C44: 4 | D44: Recovery | E44: 3 | F44: 24 | G44: 136 | H44: 151 | I44: 3 | J44: Windy | K44: 19 | L44: Trail | M44: 68 | N44: 267 | O44: 10 | P44: 6 | Q44: 14 | R44: 7.1 | S44: 65 | T44: 73.8 | U44: 2.1 | V44: 2384 | W44: 135 | X44: Recovery run
A45: 2026-03-28 | B45: 10 | C45: 6 | D45: Easy | E45: 4.3 | F45: 33 | G45: 136 | H45: 151 | I45: 3 | J45: Windy | K45: 8 | L45: Treadmill | M45: 19 | N45: 378 | O45: 5 | P45: 10 | Q45: 7 | R45: 7.2 | S45: 64 | T45: 74 | U45: 2.1 | V45: 2171 | W45: 111 | X45: Recovery run
A46: 2026-03-29 | B46: 10 | C46: 7 | D46: Long | E46: 8.4 | F46: 64 | G46: 144 | H46: 157 | I46: 5 | J46: Sunny | K46: 12 | L46: Mixed | M46: 26 | N46: 738 | O46: 7 | P46: 6 | Q46: 6 | R46: 7.3 | S46: 59 | T46: 73.7 | U46: 3.1 | V46: 2002 | W46: 118 | X46: Good pace
A47: 2026-03-30 | B47: 10 | C47: 1 | D47: Easy | E47: 4.8 | F47: 35 | G47: 133 | H47: 145 | I47: 4 | J47: Windy | K47: 23 | L47: Mixed | M47: 30 | N47: 417 | O47: 6 | P47: 6 | Q47: 7 | R47: 6.2 | S47: 65 | T47: 73.3 | U47: 3 | V47: 2409 | W47: 127 | X47: Easy effort
A48: 2026-04-01 | B48: 11 | C48: 3 | D48: Intervals | E48: 4 | F48: 26 | G48: 171 | H48: 190 | I48: 7 | J48: Cold | K48: 2 | L48: Mixed | M48: 18 | N48: 338 | O48: 10 | P48: 7 | Q48: 12 | R48: 8.5 | S48: 60 | T48: 73.9 | U48: 3.3 | V48: 2009 | W48: 105 | X48: Recovery run
... A53: 2026-04-08 | B53: 12 | C53: 3 | D53: Tempo | E53: 3.9 | F53: 24 | G53: 159 | H53: 177 | I53: 8 | J53: Hot | K53: 27 | L53: Track | M53: 24 | N53: 325 | O53: 8 | P53: 7 | Q53: 5 | R53: 8.1 | S53: 60 | T53: 73.2 | U53: 3.4 | V53: 2271 | W53: 96 | X53: Hill repeats
A54: 2026-04-09 | B54: 12 | C54: 4 | D54: Recovery | E54: 3 | F54: 24 | G54: 132 | H54: 146 | I54: 2 | J54: Cloudy | K54: 25 | L54: Mixed | M54: 24 | N54: 267 | O54: 5 | P54: 5 | Q54: 10 | R54: 6.7 | S54: 60 | T54: 73.5 | U54: 2.3 | V54: 2467 | W54: 103
A55: 2026-04-11 | B55: 12 | C55: 6 | D55: Easy | E55: 4.7 | F55: 35 | G55: 135 | H55: 143 | I55: 4 | J55: Sunny | K55: 5 | L55: Hilly | M55: 23 | N55: 410 | O55: 7 | P55: 6 | Q55: 14 | R55: 7 | S55: 60 | T55: 73 | U55: 2.2 | V55: 2331 | W55: 123 | X55: Pushed hard
A56: 2026-04-12 | B56: 12 | C56: 7 | D56: Long | E56: 8.6 | F56: 65 | G56: 147 | H56: 156 | I56: 5 | J56: Hot | K56: 34 | L56: Trail | M56: 137 | N56: 754 | O56: 10 | P56: 5 | Q56: 5 | R56: 9 | S56: 65 | T56: 73.1 | U56: 3 | V56: 2402 | W56: 135 | X56: Hot day
A57: 2026-04-16 | B57: 13 | C57: 4 | D57: Cross-Train | E57: 0 | F57: 34 | G57: 133 | H57: 147 | I57: 5 | J57: Cold | K57: 6 | L57: Trail | M57: 136 | N57: 204 | O57: 9 | P57: 9 | Q57: 11 | R57: 6.3 | S57: 64 | T57: 72.7 | U57: 3 | V57: 2464 | W57: 136 | X57: Struggled early
A58: 2026-04-18 | B58: 13 | C58: 6 | D58: Easy | E58: 4.8 | F58: 36 | G58: 145 | H58: 159 | I58: 4 | J58: Hot | K58: 30 | L58: Trail | M58: 59 | N58: 420 | O58: 10 | P58: 8 | Q58: 6 | R58: 6.3 | S58: 59 | T58: 72.6 | U58: 2.1 | V58: 2281 | W58: 98 | X58: Perfect conditions

Sheet Analysis
A1: Workout Analysis - Calculated Metrics
A3: Date | B3: Week | C3: Type | D3: Distance | E3: Time | F3: Pace (min/km) | G3: vs Target Pace | H3: Pace Zone | I3: Pace Score | J3: Avg HR | K3: HR Zone | L3: HR Efficiency | M3: Cardiac Drift | N3: Training Load | O3: Fatigue Score | P3: Recovery Need | Q3: Weekly Volume | R3: Cumulative Distance
A4: ='Workout Log'!A4 | B4: ='Workout Log'!B4 | C4: ='Workout Log'!D4 | D4: ='Workout Log'!E4 | E4: ='Workout Log'!F4 | F4: =IF(AND(D4<>"",D4>0,E4<>""),E4/D4,"") | G4: =IF(F4<>"",F4-TargetPace,"") | H4: =IF(F4="","",IF(F4<=IntervalPace,"Sprint",IF(F4<=TempoPace,"Tempo",IF(F4<=EasyPace,"Easy","Recovery")))) | I4: =IF(G4="","",IF(G4<=-0.5,10,IF(G4<=0,8,IF(G4<=0.5,6,IF(G4<=1,4,2))))) | J4: ='Workout Log'!G4 | K4: =IF(J4="","",IF(J4<=MaxHR*0.6,"Z1",IF(J4<=MaxHR*0.7,"Z2",IF(J4<=MaxHR*0.8,"Z3",IF(J4<=MaxHR*0.9,"Z4","Z5"))))) | L4: =IF(AND(F4<>"",J4<>""),ROUND(F4/(J4/100),2),"") | M4: =IF(AND('Workout Log'!G4<>"",'Workout Log'!H4<>""),'Workout Log'!H4-'Workout Log'!G4,"") | N4: =IF(AND(E4<>"",J4<>""),ROUND((E4*(J4-RestingHR)/(MaxHR-RestingHR))*10,1),"") | O4: =IF(AND('Workout Log'!I4<>"",E4<>""),ROUND('Workout Log'!I4*(E4/30),1),"") | P4: =IF(O4="","",IF(O4>=8,"High",IF(O4>=5,"Medium","Low"))) | Q4: =SUMIFS(D:D,B:B,B4) | R4: =SUM(D$4:D4)
A5: ='Workout Log'!A5 | B5: ='Workout Log'!B5 | C5: ='Workout Log'!D5 | D5: ='Workout Log'!E5 | E5: ='Workout Log'!F5 | F5: =IF(AND(D5<>"",D5>0,E5<>""),E5/D5,"") | G5: =IF(F5<>"",F5-TargetPace,"") | H5: =IF(F5="","",IF(F5<=IntervalPace,"Sprint",IF(F5<=TempoPace,"Tempo",IF(F5<=EasyPace,"Easy","Recovery")))) | I5: =IF(G5="","",IF(G5<=-0.5,10,IF(G5<=0,8,IF(G5<=0.5,6,IF(G5<=1,4,2))))) | J5: ='Workout Log'!G5 | K5: =IF(J5="","",IF(J5<=MaxHR*0.6,"Z1",IF(J5<=MaxHR*0.7,"Z2",IF(J5<=MaxHR*0.8,"Z3",IF(J5<=MaxHR*0.9,"Z4","Z5"))))) | L5: =IF(AND(F5<>"",J5<>""),ROUND(F5/(J5/100),2),"") | M5: =IF(AND('Workout Log'!G5<>"",'Workout Log'!H5<>""),'Workout Log'!H5-'Workout Log'!G5,"") | N5: =IF(AND(E5<>"",J5<>""),ROUND((E5*(J5-RestingHR)/(MaxHR-RestingHR))*10,1),"") | O5: =IF(AND('Workout Log'!I5<>"",E5<>""),ROUND('Workout Log'!I5*(E5/30),1),"") | P5: =IF(O5="","",IF(O5>=8,"High",IF(O5>=5,"Medium","Low"))) | Q5: =SUMIFS(D:D,B:B,B5) | R5: =SUM(D$4:D5)
A6: ='Workout Log'!A6 | B6: ='Workout Log'!B6 | C6: ='Workout Log'!D6 | D6: ='Workout Log'!E6 | E6: ='Workout Log'!F6 | F6: =IF(AND(D6<>"",D6>0,E6<>""),E6/D6,"") | G6: =IF(F6<>"",F6-TargetPace,"") | H6: =IF(F6="","",IF(F6<=IntervalPace,"Sprint",IF(F6<=TempoPace,"Tempo",IF(F6<=EasyPace,"Easy","Recovery")))) | I6: =IF(G6="","",IF(G6<=-0.5,10,IF(G6<=0,8,IF(G6<=0.5,6,IF(G6<=1,4,2))))) | J6: ='Workout Log'!G6 | K6: =IF(J6="","",IF(J6<=MaxHR*0.6,"Z1",IF(J6<=MaxHR*0.7,"Z2",IF(J6<=MaxHR*0.8,"Z3",IF(J6<=MaxHR*0.9,"Z4","Z5"))))) | L6: =IF(AND(F6<>"",J6<>""),ROUND(F6/(J6/100),2),"") | M6: =IF(AND('Workout Log'!G6<>"",'Workout Log'!H6<>""),'Workout Log'!H6-'Workout Log'!G6,"") | N6: =IF(AND(E6<>"",J6<>""),ROUND((E6*(J6-RestingHR)/(MaxHR-RestingHR))*10,1),"") | O6: =IF(AND('Workout Log'!I6<>"",E6<>""),ROUND('Workout Log'!I6*(E6/30),1),"") | P6: =IF(O6="","",IF(O6>=8,"High",IF(O6>=5,"Medium","Low"))) | Q6: =SUMIFS(D:D,B:B,B6) | R6: =SUM(D$4:D6)
A7: ='Workout Log'!A7 | B7: ='Workout Log'!B7 | C7: ='Workout Log'!D7 | D7: ='Workout Log'!E7 | E7: ='Workout Log'!F7 | F7: =IF(AND(D7<>"",D7>0,E7<>""),E7/D7,"") | G7: =IF(F7<>"",F7-TargetPace,"") | H7: =IF(F7="","",IF(F7<=IntervalPace,"Sprint",IF(F7<=TempoPace,"Tempo",IF(F7<=EasyPace,"Easy","Recovery")))) | I7: =IF(G7="","",IF(G7<=-0.5,10,IF(G7<=0,8,IF(G7<=0.5,6,IF(G7<=1,4,2))))) | J7: ='Workout Log'!G7 | K7: =IF(J7="","",IF(J7<=MaxHR*0.6,"Z1",IF(J7<=MaxHR*0.7,"Z2",IF(J7<=MaxHR*0.8,"Z3",IF(J7<=MaxHR*0.9,"Z4","Z5"))))) | L7: =IF(AND(F7<>"",J7<>""),ROUND(F7/(J7/100),2),"") | M7: =IF(AND('Workout Log'!G7<>"",'Workout Log'!H7<>""),'Workout Log'!H7-'Workout Log'!G7,"") | N7: =IF(AND(E7<>"",J7<>""),ROUND((E7*(J7-RestingHR)/(MaxHR-RestingHR))*10,1),"") | O7: =IF(AND('Workout Log'!I7<>"",E7<>""),ROUND('Workout Log'!I7*(E7/30),1),"") | P7: =IF(O7="","",IF(O7>=8,"High",IF(O7>=5,"Medium","Low"))) | Q7: =SUMIFS(D:D,B:B,B7) | R7: =SUM(D$4:D7)
A8: ='Workout Log'!A8 | B8: ='Workout Log'!B8 | C8: ='Workout Log'!D8 | D8: ='Workout Log'!E8 | E8: ='Workout Log'!F8 | F8: =IF(AND(D8<>"",D8>0,E8<>""),E8/D8,"") | G8: =IF(F8<>"",F8-TargetPace,"") | H8: =IF(F8="","",IF(F8<=IntervalPace,"Sprint",IF(F8<=TempoPace,"Tempo",IF(F8<=EasyPace,"Easy","Recovery")))) | I8: =IF(G8="","",IF(G8<=-0.5,10,IF(G8<=0,8,IF(G8<=0.5,6,IF(G8<=1,4,2))))) | J8: ='Workout Log'!G8 | K8: =IF(J8="","",IF(J8<=MaxHR*0.6,"Z1",IF(J8<=MaxHR*0.7,"Z2",IF(J8<=MaxHR*0.8,"Z3",IF(J8<=MaxHR*0.9,"Z4","Z5"))))) | L8: =IF(AND(F8<>"",J8<>""),ROUND(F8/(J8/100),2),"") | M8: =IF(AND('Workout Log'!G8<>"",'Workout Log'!H8<>""),'Workout Log'!H8-'Workout Log'!G8,"") | N8: =IF(AND(E8<>"",J8<>""),ROUND((E8*(J8-RestingHR)/(MaxHR-RestingHR))*10,1),"") | O8: =IF(AND('Workout Log'!I8<>"",E8<>""),ROUND('Workout Log'!I8*(E8/30),1),"") | P8: =IF(O8="","",IF(O8>=8,"High",IF(O8>=5,"Medium","Low"))) | Q8: =SUMIFS(D:D,B:B,B8) | R8: =SUM(D$4:D8)
A9: ='Workout Log'!A9 | B9: ='Workout Log'!B9 | C9: ='Workout Log'!D9 | D9: ='Workout Log'!E9 | E9: ='Workout Log'!F9 | F9: =IF(AND(D9<>"",D9>0,E9<>""),E9/D9,"") | G9: =IF(F9<>"",F9-TargetPace,"") | H9: =IF(F9="","",IF(F9<=IntervalPace,"Sprint",IF(F9<=TempoPace,"Tempo",IF(F9<=EasyPace,"Easy","Recovery")))) | I9: =IF(G9="","",IF(G9<=-0.5,10,IF(G9<=0,8,IF(G9<=0.5,6,IF(G9<=1,4,2))))) | J9: ='Workout Log'!G9 | K9: =IF(J9="","",IF(J9<=MaxHR*0.6,"Z1",IF(J9<=MaxHR*0.7,"Z2",IF(J9<=MaxHR*0.8,"Z3",IF(J9<=MaxHR*0.9,"Z4","Z5"))))) | L9: =IF(AND(F9<>"",J9<>""),ROUND(F9/(J9/100),2),"") | M9: =IF(AND('Workout Log'!G9<>"",'Workout Log'!H9<>""),'Workout Log'!H9-'Workout Log'!G9,"") | N9: =IF(AND(E9<>"",J9<>""),ROUND((E9*(J9-RestingHR)/(MaxHR-RestingHR))*10,1),"") | O9: =IF(AND('Workout Log'!I9<>"",E9<>""),ROUND('Workout Log'!I9*(E9/30),1),"") | P9: =IF(O9="","",IF(O9>=8,"High",IF(O9>=5,"Medium","Low"))) | Q9: =SUMIFS(D:D,B:B,B9) | R9: =SUM(D$4:D9)
A10: ='Workout Log'!A10 | B10: ='Workout Log'!B10 | C10: ='Workout Log'!D10 | D10: ='Workout Log'!E10 | E10: ='Workout Log'!F10 | F10: =IF(AND(D10<>"",D10>0,E10<>""),E10/D10,"") | G10: =IF(F10<>"",F10-TargetPace,"") | H10: =IF(F10="","",IF(F10<=IntervalPace,"Sprint",IF(F10<=TempoPace,"Tempo",IF(F10<=EasyPace,"Easy","Recovery")))) | I10: =IF(G10="","",IF(G10<=-0.5,10,IF(G10<=0,8,IF(G10<=0.5,6,IF(G10<=1,4,2))))) | J10: ='Workout Log'!G10 | K10: =IF(J10="","",IF(J10<=MaxHR*0.6,"Z1",IF(J10<=MaxHR*0.7,"Z2",IF(J10<=MaxHR*0.8,"Z3",IF(J10<=MaxHR*0.9,"Z4","Z5"))))) | L10: =IF(AND(F10<>"",J10<>""),ROUND(F10/(J10/100),2),"") | M10: =IF(AND('Workout Log'!G10<>"",'Workout Log'!H10<>""),'Workout Log'!H10-'Workout Log'!G10,"") | N10: =IF(AND(E10<>"",J10<>""),ROUND((E10*(J10-RestingHR)/(MaxHR-RestingHR))*10,1),"") | O10: =IF(AND('Workout Log'!I10<>"",E10<>""),ROUND('Workout Log'!I10*(E10/30),1),"") | P10: =IF(O10="","",IF(O10>=8,"High",IF(O10>=5,"Medium","Low"))) | Q10: =SUMIFS(D:D,B:B,B10) | R10: =SUM(D$4:D10)
A11: ='Workout Log'!A11 | B11: ='Workout Log'!B11 | C11: ='Workout Log'!D11 | D11: ='Workout Log'!E11 | E11: ='Workout Log'!F11 | F11: =IF(AND(D11<>"",D11>0,E11<>""),E11/D11,"") | G11: =IF(F11<>"",F11-TargetPace,"") | H11: =IF(F11="","",IF(F11<=IntervalPace,"Sprint",IF(F11<=TempoPace,"Tempo",IF(F11<=EasyPace,"Easy","Recovery")))) | I11: =IF(G11="","",IF(G11<=-0.5,10,IF(G11<=0,8,IF(G11<=0.5,6,IF(G11<=1,4,2))))) | J11: ='Workout Log'!G11 | K11: =IF(J11="","",IF(J11<=MaxHR*0.6,"Z1",IF(J11<=MaxHR*0.7,"Z2",IF(J11<=MaxHR*0.8,"Z3",IF(J11<=MaxHR*0.9,"Z4","Z5"))))) | L11: =IF(AND(F11<>"",J11<>""),ROUND(F11/(J11/100),2),"") | M11: =IF(AND('Workout Log'!G11<>"",'Workout Log'!H11<>""),'Workout Log'!H11-'Workout Log'!G11,"") | N11: =IF(AND(E11<>"",J11<>""),ROUND((E11*(J11-RestingHR)/(MaxHR-RestingHR))*10,1),"") | O11: =IF(AND('Workout Log'!I11<>"",E11<>""),ROUND('Workout Log'!I11*(E11/30),1),"") | P11: =IF(O11="","",IF(O11>=8,"High",IF(O11>=5,"Medium","Low"))) | Q11: =SUMIFS(D:D,B:B,B11) | R11: =SUM(D$4:D11)
A12: ='Workout Log'!A12 | B12: ='Workout Log'!B12 | C12: ='Workout Log'!D12 | D12: ='Workout Log'!E12 | E12: ='Workout Log'!F12 | F12: =IF(AND(D12<>"",D12>0,E12<>""),E12/D12,"") | G12: =IF(F12<>"",F12-TargetPace,"") | H12: =IF(F12="","",IF(F12<=IntervalPace,"Sprint",IF(F12<=TempoPace,"Tempo",IF(F12<=EasyPace,"Easy","Recovery")))) | I12: =IF(G12="","",IF(G12<=-0.5,10,IF(G12<=0,8,IF(G12<=0.5,6,IF(G12<=1,4,2))))) | J12: ='Workout Log'!G12 | K12: =IF(J12="","",IF(J12<=MaxHR*0.6,"Z1",IF(J12<=MaxHR*0.7,"Z2",IF(J12<=MaxHR*0.8,"Z3",IF(J12<=MaxHR*0.9,"Z4","Z5"))))) | L12: =IF(AND(F12<>"",J12<>""),ROUND(F12/(J12/100),2),"") | M12: =IF(AND('Workout Log'!G12<>"",'Workout Log'!H12<>""),'Workout Log'!H12-'Workout Log'!G12,"") | N12: =IF(AND(E12<>"",J12<>""),ROUND((E12*(J12-RestingHR)/(MaxHR-RestingHR))*10,1),"") | O12: =IF(AND('Workout Log'!I12<>"",E12<>""),ROUND('Workout Log'!I12*(E12/30),1),"") | P12: =IF(O12="","",IF(O12>=8,"High",IF(O12>=5,"Medium","Low"))) | Q12: =SUMIFS(D:D,B:B,B12) | R12: =SUM(D$4:D12)
A13: ='Workout Log'!A13 | B13: ='Workout Log'!B13 | C13: ='Workout Log'!D13 | D13: ='Workout Log'!E13 | E13: ='Workout Log'!F13 | F13: =IF(AND(D13<>"",D13>0,E13<>""),E13/D13,"") | G13: =IF(F13<>"",F13-TargetPace,"") | H13: =IF(F13="","",IF(F13<=IntervalPace,"Sprint",IF(F13<=TempoPace,"Tempo",IF(F13<=EasyPace,"Easy","Recovery")))) | I13: =IF(G13="","",IF(G13<=-0.5,10,IF(G13<=0,8,IF(G13<=0.5,6,IF(G13<=1,4,2))))) | J13: ='Workout Log'!G13 | K13: =IF(J13="","",IF(J13<=MaxHR*0.6,"Z1",IF(J13<=MaxHR*0.7,"Z2",IF(J13<=MaxHR*0.8,"Z3",IF(J13<=MaxHR*0.9,"Z4","Z5"))))) | L13: =IF(AND(F13<>"",J13<>""),ROUND(F13/(J13/100),2),"") | M13: =IF(AND('Workout Log'!G13<>"",'Workout Log'!H13<>""),'Workout Log'!H13-'Workout Log'!G13,"") | N13: =IF(AND(E13<>"",J13<>""),ROUND((E13*(J13-RestingHR)/(MaxHR-RestingHR))*10,1),"") | O13: =IF(AND('Workout Log'!I13<>"",E13<>""),ROUND('Workout Log'!I13*(E13/30),1),"") | P13: =IF(O13="","",IF(O13>=8,"High",IF(O13>=5,"Medium","Low"))) | Q13: =SUMIFS(D:D,B:B,B13) | R13: =SUM(D$4:D13)
A14: ='Workout Log'!A14 | B14: ='Workout Log'!B14 | C14: ='Workout Log'!D14 | D14: ='Workout Log'!E14 | E14: ='Workout Log'!F14 | F14: =IF(AND(D14<>"",D14>0,E14<>""),E14/D14,"") | G14: =IF(F14<>"",F14-TargetPace,"") | H14: =IF(F14="","",IF(F14<=IntervalPace,"Sprint",IF(F14<=TempoPace,"Tempo",IF(F14<=EasyPace,"Easy","Recovery")))) | I14: =IF(G14="","",IF(G14<=-0.5,10,IF(G14<=0,8,IF(G14<=0.5,6,IF(G14<=1,4,2))))) | J14: ='Workout Log'!G14 | K14: =IF(J14="","",IF(J14<=MaxHR*0.6,"Z1",IF(J14<=MaxHR*0.7,"Z2",IF(J14<=MaxHR*0.8,"Z3",IF(J14<=MaxHR*0.9,"Z4","Z5"))))) | L14: =IF(AND(F14<>"",J14<>""),ROUND(F14/(J14/100),2),"") | M14: =IF(AND('Workout Log'!G14<>"",'Workout Log'!H14<>""),'Workout Log'!H14-'Workout Log'!G14,"") | N14: =IF(AND(E14<>"",J14<>""),ROUND((E14*(J14-RestingHR)/(MaxHR-RestingHR))*10,1),"") | O14: =IF(AND('Workout Log'!I14<>"",E14<>""),ROUND('Workout Log'!I14*(E14/30),1),"") | P14: =IF(O14="","",IF(O14>=8,"High",IF(O14>=5,"Medium","Low"))) | Q14: =SUMIFS(D:D,B:B,B14) | R14: =SUM(D$4:D14)
A15: ='Workout Log'!A15 | B15: ='Workout Log'!B15 | C15: ='Workout Log'!D15 | D15: ='Workout Log'!E15 | E15: ='Workout Log'!F15 | F15: =IF(AND(D15<>"",D15>0,E15<>""),E15/D15,"") | G15: =IF(F15<>"",F15-TargetPace,"") | H15: =IF(F15="","",IF(F15<=IntervalPace,"Sprint",IF(F15<=TempoPace,"Tempo",IF(F15<=EasyPace,"Easy","Recovery")))) | I15: =IF(G15="","",IF(G15<=-0.5,10,IF(G15<=0,8,IF(G15<=0.5,6,IF(G15<=1,4,2))))) | J15: ='Workout Log'!G15 | K15: =IF(J15="","",IF(J15<=MaxHR*0.6,"Z1",IF(J15<=MaxHR*0.7,"Z2",IF(J15<=MaxHR*0.8,"Z3",IF(J15<=MaxHR*0.9,"Z4","Z5"))))) | L15: =IF(AND(F15<>"",J15<>""),ROUND(F15/(J15/100),2),"") | M15: =IF(AND('Workout Log'!G15<>"",'Workout Log'!H15<>""),'Workout Log'!H15-'Workout Log'!G15,"") | N15: =IF(AND(E15<>"",J15<>""),ROUND((E15*(J15-RestingHR)/(MaxHR-RestingHR))*10,1),"") | O15: =IF(AND('Workout Log'!I15<>"",E15<>""),ROUND('Workout Log'!I15*(E15/30),1),"") | P15: =IF(O15="","",IF(O15>=8,"High",IF(O15>=5,"Medium","Low"))) | Q15: =SUMIFS(D:D,B:B,B15) | R15: =SUM(D$4:D15)
... A58: ='Workout Log'!A58 | B58: ='Workout Log'!B58 | C58: ='Workout Log'!D58 | D58: ='Workout Log'!E58 | E58: ='Workout Log'!F58 | F58: =IF(AND(D58<>"",D58>0,E58<>""),E58/D58,"") | G58: =IF(F58<>"",F58-TargetPace,"") | H58: =IF(F58="","",IF(F58<=IntervalPace,"Sprint",IF(F58<=TempoPace,"Tempo",IF(F58<=EasyPace,"Easy","Recovery")))) | I58: =IF(G58="","",IF(G58<=-0.5,10,IF(G58<=0,8,IF(G58<=0.5,6,IF(G58<=1,4,2))))) | J58: ='Workout Log'!G58 | K58: =IF(J58="","",IF(J58<=MaxHR*0.6,"Z1",IF(J58<=MaxHR*0.7,"Z2",IF(J58<=MaxHR*0.8,"Z3",IF(J58<=MaxHR*0.9,"Z4","Z5"))))) | L58: =IF(AND(F58<>"",J58<>""),ROUND(F58/(J58/100),2),"") | M58: =IF(AND('Workout Log'!G58<>"",'Workout Log'!H58<>""),'Workout Log'!H58-'Workout Log'!G58,"") | N58: =IF(AND(E58<>"",J58<>""),ROUND((E58*(J58-RestingHR)/(MaxHR-RestingHR))*10,1),"") | O58: =IF(AND('Workout Log'!I58<>"",E58<>""),ROUND('Workout Log'!I58*(E58/30),1),"") | P58: =IF(O58="","",IF(O58>=8,"High",IF(O58>=5,"Medium","Low"))) | Q58: =SUMIFS(D:D,B:B,B58) | R58: =SUM(D$4:D58)

Sheet Dashboard
A1: 5K Training Dashboard - Progress & Insights
A3: TRAINING VOLUME | D3: RACE READINESS ASSESSMENT
A4: Total Workouts | B4: =COUNTA(Analysis!C:C)-1 | D4: Overall Status | E4: =IF(B4=0,"Not Started",IF(AND(B17<=0,B35<0),"Race Ready",IF(B17<=0.3,"On Track","Needs Work")))
A5: Total Running Workouts | B5: =COUNTIFS(Analysis!C:C,"<>",Analysis!C:C,"<>Cross-Train")-1 | D5: Pace Status | E5: =IF(B17<=0,"Ahead of Target",IF(B17<=0.5,"On Target","Behind Target"))
A6: Total Distance (km) | B6: =SUMIF(Analysis!D:D,">0") | D6: Volume Status | E6: =IF(B6>=Parameters!B11*Parameters!B12*0.8,"Good Volume","Need More Runs")
A7: Total Time (min) | B7: =SUMIF(Analysis!E:E,">0") | D7: Fitness Trend | E7: =IF(B28>0,"Improving",IF(B28<0,"Declining","Stable"))
A8: Total Time (hrs) | B8: =B7/60 | D8: Training Load | E8: =IF(AVERAGEIF(Analysis!N:N,">0")>50,"High",IF(AVERAGEIF(Analysis!N:N,">0")>30,"Moderate","Low"))
A9: Avg Distance per Run (km) | B9: =B6/B5 | D9: Days to Race | E9: =Parameters!B8-TODAY()
A10: Avg Duration per Run (min) | B10: =B7/B4 | D10: Workouts Remaining | E10: =MAX(0,(Parameters!B11-B2/7)*Parameters!B12)
A11: Longest Run (km) | B11: =MAX(Analysis!D:D) | D11: Predicted Race Time (min) | E11: =B16*5
A12: Total Calories Burned | B12: =SUM('Workout Log'!N:N) | D12: vs Target Time | E12: =B16*5-TargetTime
D13: Confidence Level | E13: =IF(E12<=0,"High",IF(E12<=2,"Medium","Low"))
A14: PACE ANALYSIS
A15: Target Race Pace (min/km) | B15: =TargetPace
A16: Current Avg Pace (min/km) | B16: =SUMIF(Analysis!E:E,">0")/SUMIF(Analysis!D:D,">0")
A17: Pace Gap (min/km) | B17: =B16-B15
A18: Best Pace Achieved (min/km) | B18: =MIN(IF(Analysis!F4:F100<>"",Analysis!F4:F100))
A19: Pace Improvement (%) | B19: =IFERROR((AVERAGE(Analysis!F4:F8)-AVERAGE(INDEX(Analysis!F:F,COUNTA(Analysis!A:A)-3):INDEX(Analysis!F:F,COUNTA(Analysis!A:A))))/AVERAGE(Analysis!F4:F8)*100,0)
A20: Avg Pace Score | B20: =AVERAGEIF(Analysis!I:I,">0")
A21: Tempo Runs Completed | B21: =COUNTIF(Analysis!H:H,"Tempo")
A22: Sprint Workouts | B22: =COUNTIF(Analysis!H:H,"Sprint")
A24: HEART RATE & FITNESS
A25: Avg Workout HR (bpm) | B25: =AVERAGEIF('Workout Log'!G:G,">0")
A26: Max HR Recorded (bpm) | B26: =MAX('Workout Log'!H:H)
A27: Avg Resting HR (bpm) | B27: =AVERAGEIF('Workout Log'!S:S,">0")
A28: Resting HR Improvement | B28: =IFERROR(AVERAGE(INDEX('Workout Log'!S:S,4):INDEX('Workout Log'!S:S,8))-AVERAGE(INDEX('Workout Log'!S:S,COUNTA('Workout Log'!A:A)-3):INDEX('Workout Log'!S:S,COUNTA('Workout Log'!A:A))),0)
A29: Avg HR Efficiency | B29: =AVERAGEIF(Analysis!L:L,">0")
A30: Z3+ Workouts (Aerobic+) | B30: =COUNTIFS(Analysis!K:K,"Z3")+COUNTIFS(Analysis!K:K,"Z4")+COUNTIFS(Analysis!K:K,"Z5")
A32: BODY METRICS
A33: Starting Weight (kg) | B33: =Parameters!B25
A34: Current Weight (kg) | B34: =IFERROR(LOOKUP(2,1/('Workout Log'!T:T<>""),'Workout Log'!T:T),Parameters!B25)
A35: Weight Change (kg) | B35: =B34-B33
A36: Target Weight (kg) | B36: =Parameters!B26
A37: Weight to Target (kg) | B37: =B34-B36
A38: Avg Sleep (hrs) | B38: =AVERAGEIF('Workout Log'!R:R,">0")
A39: Avg Hydration (L) | B39: =AVERAGEIF('Workout Log'!U:U,">0")
A45: WEEKLY BREAKDOWN
A46: Week | B46: Workouts | C46: Distance (km) | D46: Time (min) | E46: Avg Pace | F46: Avg HR | G46: Avg Quality
A47: Week 1 | B47: =COUNTIF(Analysis!B:B,1) | C47: =SUMIF(Analysis!B:B,1,Analysis!D:D) | D47: =SUMIF(Analysis!B:B,1,Analysis!E:E) | E47: =IF(B47>0,SUMIFS(Analysis!E:E,Analysis!B:B,1)/SUMIFS(Analysis!D:D,Analysis!B:B,1),"") | F47: =IF(B47>0,AVERAGEIFS('Workout Log'!G:G,'Workout Log'!B:B,1,'Workout Log'!G:G,">0"),"") | G47: =IF(B47>0,AVERAGEIFS(Analysis!I:I,Analysis!B:B,1,Analysis!I:I,">0"),"")
A48: Week 2 | B48: =COUNTIF(Analysis!B:B,2) | C48: =SUMIF(Analysis!B:B,2,Analysis!D:D) | D48: =SUMIF(Analysis!B:B,2,Analysis!E:E) | E48: =IF(B48>0,SUMIFS(Analysis!E:E,Analysis!B:B,2)/SUMIFS(Analysis!D:D,Analysis!B:B,2),"") | F48: =IF(B48>0,AVERAGEIFS('Workout Log'!G:G,'Workout Log'!B:B,2,'Workout Log'!G:G,">0"),"") | G48: =IF(B48>0,AVERAGEIFS(Analysis!I:I,Analysis!B:B,2,Analysis!I:I,">0"),"")
...
