Workbook

Sheet Parameters
A1: BD Prospecting - Parameters
A3: SCORING WEIGHTS
A4: Parameter | B4: Value | C4: Description
A5: Fit Weight | B5: 0.4 | C5: Weight for company fit score
A6: Intent Weight | B6: 0.35 | C6: Weight for buying intent signals
A7: Engagement Weight | B7: 0.25 | C7: Weight for past engagement
A9: FIT CRITERIA
A10: Parameter | B10: Value | C10: Description
A11: Target Industry 1 | B11: SaaS | C11: Primary target
A12: Target Industry 2 | B12: FinTech | C12: Primary target
A13: Target Industry 3 | B13: HealthTech | C13: Primary target
A14: Adjacent Industry 1 | B14: Manufacturing | C14: Partial credit
A15: Adjacent Industry 2 | B15: Retail | C15: Partial credit
A16: Min Employees | B16: 50 | C16: Below = 0 fit score
A17: Max Employees | B17: 1000 | C17: Above = reduced fit
A18: Ideal Emp Min | B18: 200 | C18: Full points range start
A19: Ideal Emp Max | B19: 500 | C19: Full points range end
A20: Target Geo 1 | B20: US | C20: Primary geography
A21: Target Geo 2 | B21: UK | C21: Primary geography
A22: Target Geo 3 | B22: CA | C22: Primary geography
A24: INTENT SCORING
A25: Parameter | B25: Value | C25: Description
A26: Points per Website Visit | B26: 10 | C26: Recency-weighted
A27: Points per Content Download | B27: 25 | C27: High-value signal
A28: Points per Event Attendance | B28: 40 | C28: Strongest signal
A29: Intent Decay Days | B29: 30 | C29: Half-life for signals
A30: Max Visit Score | B30: 40 | C30: Cap for visit points
A31: Max Content Score | B31: 50 | C31: Cap for content points
A32: Max Event Score | B32: 60 | C32: Cap for event points
A34: ENGAGEMENT SCORING
A35: Parameter | B35: Value | C35: Description
A36: Points per Email Open | B36: 5 | C36: Basic engagement
A37: Points per Email Reply | B37: 30 | C37: Strong signal
A38: Points per Meeting Held | B38: 50 | C38: Strongest engagement
A39: Staleness Penalty per Day | B39: -2 | C39: Decay for no contact
A40: Max Staleness Penalty | B40: -40 | C40: Floor for penalty
A42: TIER THRESHOLDS
A43: Parameter | B43: Value | C43: Description
A44: Hot Threshold | B44: 80 | C44: Immediate action needed
A45: Warm Threshold | B45: 60 | C45: Active pursuit
...

Sheet Raw Data
A1: Company ID | B1: Company Name | C1: Industry | D1: Employee Count | E1: Revenue ($M) | F1: HQ Country | G1: Primary Contact | H1: Contact Title | I1: Contact Email | J1: Website Visits (30d) | K1: Content Downloads (30d) | L1: Event Registrations | M1: Emails Sent | N1: Email Opens | O1: Email Replies | P1: Meetings Held | Q1: Last Touch Date | R1: Trigger Event | S1: Owner | T1: Notes
A2: COMP-001 | B2: TechFlow Solutions | C2: SaaS | D2: 320 | E2: 45 | F2: US | G2: Sarah Chen | H2: VP Sales | I2: schen@techflow.com | J2: 8 | K2: 2 | L2: 1 | M2: 5 | N2: 4 | O2: 2 | P2: 1 | Q2: 45636 | R2: Series B Funding | S2: John D | T2: Met at conference
A3: COMP-002 | B3: DataPrime Inc | C3: FinTech | D3: 180 | E3: 28 | F3: US | G3: Mike Johnson | H3: CTO | I3: mjohnson@dataprime.io | J3: 12 | K3: 3 | L3: 0 | M3: 8 | N3: 6 | O3: 1 | P3: 0 | Q3: 45631 | S3: Sarah M | T3: Competitor user
A4: COMP-003 | B4: HealthSync Pro | C4: HealthTech | D4: 450 | E4: 72 | F4: UK | G4: Emma Wilson | H4: CEO | I4: ewilson@healthsync.co.uk | J4: 3 | K4: 0 | L4: 2 | M4: 3 | N4: 1 | O4: 0 | P4: 0 | Q4: 45616 | R4: New CEO hired | S4: John D
A5: COMP-004 | B5: CloudNine Systems | C5: SaaS | D5: 85 | E5: 12 | F5: CA | G5: David Lee | H5: Director Ops | I5: dlee@cloudnine.ca | J5: 15 | K5: 4 | L5: 1 | M5: 10 | N5: 8 | O5: 3 | P5: 2 | Q5: 45638 | S5: Sarah M | T5: Very engaged
A6: COMP-005 | B6: RetailMax Corp | C6: Retail | D6: 2500 | E6: 340 | F6: US | G6: Jennifer Adams | H6: VP IT | I6: jadams@retailmax.com | J6: 2 | K6: 1 | L6: 0 | M6: 4 | N6: 2 | O6: 0 | P6: 0 | Q6: 45580 | S6: Mike T | T6: Large enterprise
A7: COMP-006 | B7: ManuTech Industries | C7: Manufacturing | D7: 620 | E7: 95 | F7: US | G7: Robert Brown | H7: Plant Manager | I7: rbrown@manutech.com | J7: 5 | K7: 1 | L7: 1 | M7: 6 | N7: 3 | O7: 1 | P7: 0 | Q7: 45624 | R7: Expansion announced | S7: John D | T7: Adjacent industry
A8: COMP-007 | B8: FinServe Global | C8: FinTech | D8: 290 | E8: 52 | F8: UK | G8: Lisa Park | H8: CFO | I8: lpark@finserve.co.uk | J8: 20 | K8: 5 | L8: 2 | M8: 12 | N8: 10 | O8: 4 | P8: 1 | Q8: 45637 | R8: IPO planned | S8: Sarah M | T8: Hot prospect
A9: COMP-008 | B9: SmallBiz Tools | C9: SaaS | D9: 25 | E9: 3 | F9: US | G9: Tom Garcia | H9: Founder | I9: tgarcia@smallbiz.io | J9: 6 | K9: 2 | L9: 0 | M9: 2 | N9: 1 | O9: 0 | P9: 0 | Q9: 45634 | S9: Mike T | T9: Too small?
A10: COMP-009 | B10: MedDevice Plus | C10: HealthTech | D10: 380 | E10: 65 | F10: CA | G10: Anna Schmidt | H10: COO | I10: aschmidt@meddevice.ca | J10: 4 | K10: 1 | L10: 1 | M10: 7 | N10: 5 | O10: 2 | P10: 1 | Q10: 45627 | S10: John D | T10: Good fit
A11: COMP-010 | B11: OldSchool Mfg | C11: Manufacturing | D11: 150 | E11: 22 | F11: US | G11: Bill Thompson | H11: Owner | I11: bthompson@oldschool.com | J11: 0 | K11: 0 | L11: 0 | M11: 3 | N11: 0 | O11: 0 | P11: 0 | Q11: 45536 | S11: Mike T | T11: No engagement

Sheet Processing
A1: Company ID | B1: Company Name | C1: Industry Match | D1: Size Match | E1: Geo Match | F1: Fit Score | G1: Visit Score | H1: Content Score | I1: Event Score | J1: Intent Score | K1: Open Score | L1: Reply Score | M1: Meeting Score | N1: Staleness Adj | O1: Engage Score | P1: Composite Score | Q1: Timing Adj | R1: Final Score
A2: ='Raw Data'!A2 | B2: ='Raw Data'!B2 | C2: =IF(OR('Raw Data'!C2=Parameters!$B$11,'Raw Data'!C2=Parameters!$B$12,'Raw Data'!C2=Parameters!$B$13),100,IF(OR('Raw Data'!C2=Parameters!$B$14,'Raw Data'!C2=Parameters!$B$15),50,0)) | D2: =IF(AND('Raw Data'!D2>=Parameters!$B$18,'Raw Data'!D2<=Parameters!$B$19),100,IF(AND('Raw Data'!D2>=Parameters!$B$16,'Raw Data'!D2<=Parameters!$B$17),60,0)) | E2: =IF(OR('Raw Data'!F2=Parameters!$B$20,'Raw Data'!F2=Parameters!$B$21,'Raw Data'!F2=Parameters!$B$22),100,40) | F2: =AVERAGE(C2:E2) | G2: =MIN('Raw Data'!J2*Parameters!$B$26,Parameters!$B$30) | H2: =MIN('Raw Data'!K2*Parameters!$B$27,Parameters!$B$31) | I2: =MIN('Raw Data'!L2*Parameters!$B$28,Parameters!$B$32) | J2: =MIN(G2+H2+I2,100) | K2: ='Raw Data'!N2*Parameters!$B$36 | L2: ='Raw Data'!O2*Parameters!$B$37 | M2: ='Raw Data'!P2*Parameters!$B$38 | N2: =MAX(Parameters!$B$40,(TODAY()-'Raw Data'!Q2)*Parameters!$B$39) | O2: =MAX(0,MIN(K2+L2+M2+N2,100)) | P2: =F2*Parameters!$B$5+J2*Parameters!$B$6+O2*Parameters!$B$7 | Q2: =IF(AND(MONTH(TODAY())>=Parameters!$B$51,MONTH(TODAY())<=Parameters!$B$52),Parameters!$B$49,0)+IF('Raw Data'!R2<>"",Parameters!$B$50,0) | R2: =MIN(P2+Q2,100)
A3: ='Raw Data'!A3 | B3: ='Raw Data'!B3 | C3: =IF(OR('Raw Data'!C3=Parameters!$B$11,'Raw Data'!C3=Parameters!$B$12,'Raw Data'!C3=Parameters!$B$13),100,IF(OR('Raw Data'!C3=Parameters!$B$14,'Raw Data'!C3=Parameters!$B$15),50,0)) | D3: =IF(AND('Raw Data'!D3>=Parameters!$B$18,'Raw Data'!D3<=Parameters!$B$19),100,IF(AND('Raw Data'!D3>=Parameters!$B$16,'Raw Data'!D3<=Parameters!$B$17),60,0)) | E3: =IF(OR('Raw Data'!F3=Parameters!$B$20,'Raw Data'!F3=Parameters!$B$21,'Raw Data'!F3=Parameters!$B$22),100,40) | F3: =AVERAGE(C3:E3) | G3: =MIN('Raw Data'!J3*Parameters!$B$26,Parameters!$B$30) | H3: =MIN('Raw Data'!K3*Parameters!$B$27,Parameters!$B$31) | I3: =MIN('Raw Data'!L3*Parameters!$B$28,Parameters!$B$32) | J3: =MIN(G3+H3+I3,100) | K3: ='Raw Data'!N3*Parameters!$B$36 | L3: ='Raw Data'!O3*Parameters!$B$37 | M3: ='Raw Data'!P3*Parameters!$B$38 | N3: =MAX(Parameters!$B$40,(TODAY()-'Raw Data'!Q3)*Parameters!$B$39) | O3: =MAX(0,MIN(K3+L3+M3+N3,100)) | P3: =F3*Parameters!$B$5+J3*Parameters!$B$6+O3*Parameters!$B$7 | Q3: =IF(AND(MONTH(TODAY())>=Parameters!$B$51,MONTH(TODAY())<=Parameters!$B$52),Parameters!$B$49,0)+IF('Raw Data'!R3<>"",Parameters!$B$50,0) | R3: =MIN(P3+Q3,100)
A4: ='Raw Data'!A4 | B4: ='Raw Data'!B4 | C4: =IF(OR('Raw Data'!C4=Parameters!$B$11,'Raw Data'!C4=Parameters!$B$12,'Raw Data'!C4=Parameters!$B$13),100,IF(OR('Raw Data'!C4=Parameters!$B$14,'Raw Data'!C4=Parameters!$B$15),50,0)) | D4: =IF(AND('Raw Data'!D4>=Parameters!$B$18,'Raw Data'!D4<=Parameters!$B$19),100,IF(AND('Raw Data'!D4>=Parameters!$B$16,'Raw Data'!D4<=Parameters!$B$17),60,0)) | E4: =IF(OR('Raw Data'!F4=Parameters!$B$20,'Raw Data'!F4=Parameters!$B$21,'Raw Data'!F4=Parameters!$B$22),100,40) | F4: =AVERAGE(C4:E4) | G4: =MIN('Raw Data'!J4*Parameters!$B$26,Parameters!$B$30) | H4: =MIN('Raw Data'!K4*Parameters!$B$27,Parameters!$B$31) | I4: =MIN('Raw Data'!L4*Parameters!$B$28,Parameters!$B$32) | J4: =MIN(G4+H4+I4,100) | K4: ='Raw Data'!N4*Parameters!$B$36 | L4: ='Raw Data'!O4*Parameters!$B$37 | M4: ='Raw Data'!P4*Parameters!$B$38 | N4: =MAX(Parameters!$B$40,(TODAY()-'Raw Data'!Q4)*Parameters!$B$39) | O4: =MAX(0,MIN(K4+L4+M4+N4,100)) | P4: =F4*Parameters!$B$5+J4*Parameters!$B$6+O4*Parameters!$B$7 | Q4: =IF(AND(MONTH(TODAY())>=Parameters!$B$51,MONTH(TODAY())<=Parameters!$B$52),Parameters!$B$49,0)+IF('Raw Data'!R4<>"",Parameters!$B$50,0) | R4: =MIN(P4+Q4,100)
A5: ='Raw Data'!A5 | B5: ='Raw Data'!B5 | C5: =IF(OR('Raw Data'!C5=Parameters!$B$11,'Raw Data'!C5=Parameters!$B$12,'Raw Data'!C5=Parameters!$B$13),100,IF(OR('Raw Data'!C5=Parameters!$B$14,'Raw Data'!C5=Parameters!$B$15),50,0)) | D5: =IF(AND('Raw Data'!D5>=Parameters!$B$18,'Raw Data'!D5<=Parameters!$B$19),100,IF(AND('Raw Data'!D5>=Parameters!$B$16,'Raw Data'!D5<=Parameters!$B$17),60,0)) | E5: =IF(OR('Raw Data'!F5=Parameters!$B$20,'Raw Data'!F5=Parameters!$B$21,'Raw Data'!F5=Parameters!$B$22),100,40) | F5: =AVERAGE(C5:E5) | G5: =MIN('Raw Data'!J5*Parameters!$B$26,Parameters!$B$30) | H5: =MIN('Raw Data'!K5*Parameters!$B$27,Parameters!$B$31) | I5: =MIN('Raw Data'!L5*Parameters!$B$28,Parameters!$B$32) | J5: =MIN(G5+H5+I5,100) | K5: ='Raw Data'!N5*Parameters!$B$36 | L5: ='Raw Data'!O5*Parameters!$B$37 | M5: ='Raw Data'!P5*Parameters!$B$38 | N5: =MAX(Parameters!$B$40,(TODAY()-'Raw Data'!Q5)*Parameters!$B$39) | O5: =MAX(0,MIN(K5+L5+M5+N5,100)) | P5: =F5*Parameters!$B$5+J5*Parameters!$B$6+O5*Parameters!$B$7 | Q5: =IF(AND(MONTH(TODAY())>=Parameters!$B$51,MONTH(TODAY())<=Parameters!$B$52),Parameters!$B$49,0)+IF('Raw Data'!R5<>"",Parameters!$B$50,0) | R5: =MIN(P5+Q5,100)
A6: ='Raw Data'!A6 | B6: ='Raw Data'!B6 | C6: =IF(OR('Raw Data'!C6=Parameters!$B$11,'Raw Data'!C6=Parameters!$B$12,'Raw Data'!C6=Parameters!$B$13),100,IF(OR('Raw Data'!C6=Parameters!$B$14,'Raw Data'!C6=Parameters!$B$15),50,0)) | D6: =IF(AND('Raw Data'!D6>=Parameters!$B$18,'Raw Data'!D6<=Parameters!$B$19),100,IF(AND('Raw Data'!D6>=Parameters!$B$16,'Raw Data'!D6<=Parameters!$B$17),60,0)) | E6: =IF(OR('Raw Data'!F6=Parameters!$B$20,'Raw Data'!F6=Parameters!$B$21,'Raw Data'!F6=Parameters!$B$22),100,40) | F6: =AVERAGE(C6:E6) | G6: =MIN('Raw Data'!J6*Parameters!$B$26,Parameters!$B$30) | H6: =MIN('Raw Data'!K6*Parameters!$B$27,Parameters!$B$31) | I6: =MIN('Raw Data'!L6*Parameters!$B$28,Parameters!$B$32) | J6: =MIN(G6+H6+I6,100) | K6: ='Raw Data'!N6*Parameters!$B$36 | L6: ='Raw Data'!O6*Parameters!$B$37 | M6: ='Raw Data'!P6*Parameters!$B$38 | N6: =MAX(Parameters!$B$40,(TODAY()-'Raw Data'!Q6)*Parameters!$B$39) | O6: =MAX(0,MIN(K6+L6+M6+N6,100)) | P6: =F6*Parameters!$B$5+J6*Parameters!$B$6+O6*Parameters!$B$7 | Q6: =IF(AND(MONTH(TODAY())>=Parameters!$B$51,MONTH(TODAY())<=Parameters!$B$52),Parameters!$B$49,0)+IF('Raw Data'!R6<>"",Parameters!$B$50,0) | R6: =MIN(P6+Q6,100)
A7: ='Raw Data'!A7 | B7: ='Raw Data'!B7 | C7: =IF(OR('Raw Data'!C7=Parameters!$B$11,'Raw Data'!C7=Parameters!$B$12,'Raw Data'!C7=Parameters!$B$13),100,IF(OR('Raw Data'!C7=Parameters!$B$14,'Raw Data'!C7=Parameters!$B$15),50,0)) | D7: =IF(AND('Raw Data'!D7>=Parameters!$B$18,'Raw Data'!D7<=Parameters!$B$19),100,IF(AND('Raw Data'!D7>=Parameters!$B$16,'Raw Data'!D7<=Parameters!$B$17),60,0)) | E7: =IF(OR('Raw Data'!F7=Parameters!$B$20,'Raw Data'!F7=Parameters!$B$21,'Raw Data'!F7=Parameters!$B$22),100,40) | F7: =AVERAGE(C7:E7) | G7: =MIN('Raw Data'!J7*Parameters!$B$26,Parameters!$B$30) | H7: =MIN('Raw Data'!K7*Parameters!$B$27,Parameters!$B$31) | I7: =MIN('Raw Data'!L7*Parameters!$B$28,Parameters!$B$32) | J7: =MIN(G7+H7+I7,100) | K7: ='Raw Data'!N7*Parameters!$B$36 | L7: ='Raw Data'!O7*Parameters!$B$37 | M7: ='Raw Data'!P7*Parameters!$B$38 | N7: =MAX(Parameters!$B$40,(TODAY()-'Raw Data'!Q7)*Parameters!$B$39) | O7: =MAX(0,MIN(K7+L7+M7+N7,100)) | P7: =F7*Parameters!$B$5+J7*Parameters!$B$6+O7*Parameters!$B$7 | Q7: =IF(AND(MONTH(TODAY())>=Parameters!$B$51,MONTH(TODAY())<=Parameters!$B$52),Parameters!$B$49,0)+IF('Raw Data'!R7<>"",Parameters!$B$50,0) | R7: =MIN(P7+Q7,100)
A8: ='Raw Data'!A8 | B8: ='Raw Data'!B8 | C8: =IF(OR('Raw Data'!C8=Parameters!$B$11,'Raw Data'!C8=Parameters!$B$12,'Raw Data'!C8=Parameters!$B$13),100,IF(OR('Raw Data'!C8=Parameters!$B$14,'Raw Data'!C8=Parameters!$B$15),50,0)) | D8: =IF(AND('Raw Data'!D8>=Parameters!$B$18,'Raw Data'!D8<=Parameters!$B$19),100,IF(AND('Raw Data'!D8>=Parameters!$B$16,'Raw Data'!D8<=Parameters!$B$17),60,0)) | E8: =IF(OR('Raw Data'!F8=Parameters!$B$20,'Raw Data'!F8=Parameters!$B$21,'Raw Data'!F8=Parameters!$B$22),100,40) | F8: =AVERAGE(C8:E8) | G8: =MIN('Raw Data'!J8*Parameters!$B$26,Parameters!$B$30) | H8: =MIN('Raw Data'!K8*Parameters!$B$27,Parameters!$B$31) | I8: =MIN('Raw Data'!L8*Parameters!$B$28,Parameters!$B$32) | J8: =MIN(G8+H8+I8,100) | K8: ='Raw Data'!N8*Parameters!$B$36 | L8: ='Raw Data'!O8*Parameters!$B$37 | M8: ='Raw Data'!P8*Parameters!$B$38 | N8: =MAX(Parameters!$B$40,(TODAY()-'Raw Data'!Q8)*Parameters!$B$39) | O8: =MAX(0,MIN(K8+L8+M8+N8,100)) | P8: =F8*Parameters!$B$5+J8*Parameters!$B$6+O8*Parameters!$B$7 | Q8: =IF(AND(MONTH(TODAY())>=Parameters!$B$51,MONTH(TODAY())<=Parameters!$B$52),Parameters!$B$49,0)+IF('Raw Data'!R8<>"",Parameters!$B$50,0) | R8: =MIN(P8+Q8,100)
A9: ='Raw Data'!A9 | B9: ='Raw Data'!B9 | C9: =IF(OR('Raw Data'!C9=Parameters!$B$11,'Raw Data'!C9=Parameters!$B$12,'Raw Data'!C9=Parameters!$B$13),100,IF(OR('Raw Data'!C9=Parameters!$B$14,'Raw Data'!C9=Parameters!$B$15),50,0)) | D9: =IF(AND('Raw Data'!D9>=Parameters!$B$18,'Raw Data'!D9<=Parameters!$B$19),100,IF(AND('Raw Data'!D9>=Parameters!$B$16,'Raw Data'!D9<=Parameters!$B$17),60,0)) | E9: =IF(OR('Raw Data'!F9=Parameters!$B$20,'Raw Data'!F9=Parameters!$B$21,'Raw Data'!F9=Parameters!$B$22),100,40) | F9: =AVERAGE(C9:E9) | G9: =MIN('Raw Data'!J9*Parameters!$B$26,Parameters!$B$30) | H9: =MIN('Raw Data'!K9*Parameters!$B$27,Parameters!$B$31) | I9: =MIN('Raw Data'!L9*Parameters!$B$28,Parameters!$B$32) | J9: =MIN(G9+H9+I9,100) | K9: ='Raw Data'!N9*Parameters!$B$36 | L9: ='Raw Data'!O9*Parameters!$B$37 | M9: ='Raw Data'!P9*Parameters!$B$38 | N9: =MAX(Parameters!$B$40,(TODAY()-'Raw Data'!Q9)*Parameters!$B$39) | O9: =MAX(0,MIN(K9+L9+M9+N9,100)) | P9: =F9*Parameters!$B$5+J9*Parameters!$B$6+O9*Parameters!$B$7 | Q9: =IF(AND(MONTH(TODAY())>=Parameters!$B$51,MONTH(TODAY())<=Parameters!$B$52),Parameters!$B$49,0)+IF('Raw Data'!R9<>"",Parameters!$B$50,0) | R9: =MIN(P9+Q9,100)
A10: ='Raw Data'!A10 | B10: ='Raw Data'!B10 | C10: =IF(OR('Raw Data'!C10=Parameters!$B$11,'Raw Data'!C10=Parameters!$B$12,'Raw Data'!C10=Parameters!$B$13),100,IF(OR('Raw Data'!C10=Parameters!$B$14,'Raw Data'!C10=Parameters!$B$15),50,0)) | D10: =IF(AND('Raw Data'!D10>=Parameters!$B$18,'Raw Data'!D10<=Parameters!$B$19),100,IF(AND('Raw Data'!D10>=Parameters!$B$16,'Raw Data'!D10<=Parameters!$B$17),60,0)) | E10: =IF(OR('Raw Data'!F10=Parameters!$B$20,'Raw Data'!F10=Parameters!$B$21,'Raw Data'!F10=Parameters!$B$22),100,40) | F10: =AVERAGE(C10:E10) | G10: =MIN('Raw Data'!J10*Parameters!$B$26,Parameters!$B$30) | H10: =MIN('Raw Data'!K10*Parameters!$B$27,Parameters!$B$31) | I10: =MIN('Raw Data'!L10*Parameters!$B$28,Parameters!$B$32) | J10: =MIN(G10+H10+I10,100) | K10: ='Raw Data'!N10*Parameters!$B$36 | L10: ='Raw Data'!O10*Parameters!$B$37 | M10: ='Raw Data'!P10*Parameters!$B$38 | N10: =MAX(Parameters!$B$40,(TODAY()-'Raw Data'!Q10)*Parameters!$B$39) | O10: =MAX(0,MIN(K10+L10+M10+N10,100)) | P10: =F10*Parameters!$B$5+J10*Parameters!$B$6+O10*Parameters!$B$7 | Q10: =IF(AND(MONTH(TODAY())>=Parameters!$B$51,MONTH(TODAY())<=Parameters!$B$52),Parameters!$B$49,0)+IF('Raw Data'!R10<>"",Parameters!$B$50,0) | R10: =MIN(P10+Q10,100)
A11: ='Raw Data'!A11 | B11: ='Raw Data'!B11 | C11: =IF(OR('Raw Data'!C11=Parameters!$B$11,'Raw Data'!C11=Parameters!$B$12,'Raw Data'!C11=Parameters!$B$13),100,IF(OR('Raw Data'!C11=Parameters!$B$14,'Raw Data'!C11=Parameters!$B$15),50,0)) | D11: =IF(AND('Raw Data'!D11>=Parameters!$B$18,'Raw Data'!D11<=Parameters!$B$19),100,IF(AND('Raw Data'!D11>=Parameters!$B$16,'Raw Data'!D11<=Parameters!$B$17),60,0)) | E11: =IF(OR('Raw Data'!F11=Parameters!$B$20,'Raw Data'!F11=Parameters!$B$21,'Raw Data'!F11=Parameters!$B$22),100,40) | F11: =AVERAGE(C11:E11) | G11: =MIN('Raw Data'!J11*Parameters!$B$26,Parameters!$B$30) | H11: =MIN('Raw Data'!K11*Parameters!$B$27,Parameters!$B$31) | I11: =MIN('Raw Data'!L11*Parameters!$B$28,Parameters!$B$32) | J11: =MIN(G11+H11+I11,100) | K11: ='Raw Data'!N11*Parameters!$B$36 | L11: ='Raw Data'!O11*Parameters!$B$37 | M11: ='Raw Data'!P11*Parameters!$B$38 | N11: =MAX(Parameters!$B$40,(TODAY()-'Raw Data'!Q11)*Parameters!$B$39) | O11: =MAX(0,MIN(K11+L11+M11+N11,100)) | P11: =F11*Parameters!$B$5+J11*Parameters!$B$6+O11*Parameters!$B$7 | Q11: =IF(AND(MONTH(TODAY())>=Parameters!$B$51,MONTH(TODAY())<=Parameters!$B$52),Parameters!$B$49,0)+IF('Raw Data'!R11<>"",Parameters!$B$50,0) | R11: =MIN(P11+Q11,100)

Sheet Output
A1: Company ID | B1: Company Name | C1: Final Score | D1: Priority Tier | E1: Recommended Channel | F1: Cadence | G1: Next Action | H1: Days Since Touch | I1: Owner | J1: Talking Points
A2: =Processing!A2 | B2: =Processing!B2 | C2: =Processing!R2 | D2: =IF(C2>=Parameters!$B$44,"HOT",IF(C2>=Parameters!$B$45,"WARM",IF(C2>=Parameters!$B$46,"NURTURE","DISQUALIFY"))) | E2: =IF('Raw Data'!P2>0,"Call",IF('Raw Data'!O2>0,"Email",IF('Raw Data'!N2>2,"LinkedIn","Cold Email"))) | F2: =IF(D2="HOT","Daily",IF(D2="WARM","2x/Week",IF(D2="NURTURE","Monthly","None"))) | G2: =IF('Raw Data'!P2=0,"Book intro call",IF('Raw Data'!O2=0,"Send follow-up","Schedule demo")) | H2: =TODAY()-'Raw Data'!Q2 | I2: ='Raw Data'!S2 | J2: =IF('Raw Data'!R2<>"","Discuss: "&'Raw Data'!R2,IF('Raw Data'!C2="SaaS","SaaS growth challenges",IF('Raw Data'!C2="FinTech","Compliance & scale","Efficiency gains")))
A3: =Processing!A3 | B3: =Processing!B3 | C3: =Processing!R3 | D3: =IF(C3>=Parameters!$B$44,"HOT",IF(C3>=Parameters!$B$45,"WARM",IF(C3>=Parameters!$B$46,"NURTURE","DISQUALIFY"))) | E3: =IF('Raw Data'!P3>0,"Call",IF('Raw Data'!O3>0,"Email",IF('Raw Data'!N3>2,"LinkedIn","Cold Email"))) | F3: =IF(D3="HOT","Daily",IF(D3="WARM","2x/Week",IF(D3="NURTURE","Monthly","None"))) | G3: =IF('Raw Data'!P3=0,"Book intro call",IF('Raw Data'!O3=0,"Send follow-up","Schedule demo")) | H3: =TODAY()-'Raw Data'!Q3 | I3: ='Raw Data'!S3 | J3: =IF('Raw Data'!R3<>"","Discuss: "&'Raw Data'!R3,IF('Raw Data'!C3="SaaS","SaaS growth challenges",IF('Raw Data'!C3="FinTech","Compliance & scale","Efficiency gains")))
A4: =Processing!A4 | B4: =Processing!B4 | C4: =Processing!R4 | D4: =IF(C4>=Parameters!$B$44,"HOT",IF(C4>=Parameters!$B$45,"WARM",IF(C4>=Parameters!$B$46,"NURTURE","DISQUALIFY"))) | E4: =IF('Raw Data'!P4>0,"Call",IF('Raw Data'!O4>0,"Email",IF('Raw Data'!N4>2,"LinkedIn","Cold Email"))) | F4: =IF(D4="HOT","Daily",IF(D4="WARM","2x/Week",IF(D4="NURTURE","Monthly","None"))) | G4: =IF('Raw Data'!P4=0,"Book intro call",IF('Raw Data'!O4=0,"Send follow-up","Schedule demo")) | H4: =TODAY()-'Raw Data'!Q4 | I4: ='Raw Data'!S4 | J4: =IF('Raw Data'!R4<>"","Discuss: "&'Raw Data'!R4,IF('Raw Data'!C4="SaaS","SaaS growth challenges",IF('Raw Data'!C4="FinTech","Compliance & scale","Efficiency gains")))
A5: =Processing!A5 | B5: =Processing!B5 | C5: =Processing!R5 | D5: =IF(C5>=Parameters!$B$44,"HOT",IF(C5>=Parameters!$B$45,"WARM",IF(C5>=Parameters!$B$46,"NURTURE","DISQUALIFY"))) | E5: =IF('Raw Data'!P5>0,"Call",IF('Raw Data'!O5>0,"Email",IF('Raw Data'!N5>2,"LinkedIn","Cold Email"))) | F5: =IF(D5="HOT","Daily",IF(D5="WARM","2x/Week",IF(D5="NURTURE","Monthly","None"))) | G5: =IF('Raw Data'!P5=0,"Book intro call",IF('Raw Data'!O5=0,"Send follow-up","Schedule demo")) | H5: =TODAY()-'Raw Data'!Q5 | I5: ='Raw Data'!S5 | J5: =IF('Raw Data'!R5<>"","Discuss: "&'Raw Data'!R5,IF('Raw Data'!C5="SaaS","SaaS growth challenges",IF('Raw Data'!C5="FinTech","Compliance & scale","Efficiency gains")))
A6: =Processing!A6 | B6: =Processing!B6 | C6: =Processing!R6 | D6: =IF(C6>=Parameters!$B$44,"HOT",IF(C6>=Parameters!$B$45,"WARM",IF(C6>=Parameters!$B$46,"NURTURE","DISQUALIFY"))) | E6: =IF('Raw Data'!P6>0,"Call",IF('Raw Data'!O6>0,"Email",IF('Raw Data'!N6>2,"LinkedIn","Cold Email"))) | F6: =IF(D6="HOT","Daily",IF(D6="WARM","2x/Week",IF(D6="NURTURE","Monthly","None"))) | G6: =IF('Raw Data'!P6=0,"Book intro call",IF('Raw Data'!O6=0,"Send follow-up","Schedule demo")) | H6: =TODAY()-'Raw Data'!Q6 | I6: ='Raw Data'!S6 | J6: =IF('Raw Data'!R6<>"","Discuss: "&'Raw Data'!R6,IF('Raw Data'!C6="SaaS","SaaS growth challenges",IF('Raw Data'!C6="FinTech","Compliance & scale","Efficiency gains")))
A7: =Processing!A7 | B7: =Processing!B7 | C7: =Processing!R7 | D7: =IF(C7>=Parameters!$B$44,"HOT",IF(C7>=Parameters!$B$45,"WARM",IF(C7>=Parameters!$B$46,"NURTURE","DISQUALIFY"))) | E7: =IF('Raw Data'!P7>0,"Call",IF('Raw Data'!O7>0,"Email",IF('Raw Data'!N7>2,"LinkedIn","Cold Email"))) | F7: =IF(D7="HOT","Daily",IF(D7="WARM","2x/Week",IF(D7="NURTURE","Monthly","None"))) | G7: =IF('Raw Data'!P7=0,"Book intro call",IF('Raw Data'!O7=0,"Send follow-up","Schedule demo")) | H7: =TODAY()-'Raw Data'!Q7 | I7: ='Raw Data'!S7 | J7: =IF('Raw Data'!R7<>"","Discuss: "&'Raw Data'!R7,IF('Raw Data'!C7="SaaS","SaaS growth challenges",IF('Raw Data'!C7="FinTech","Compliance & scale","Efficiency gains")))
A8: =Processing!A8 | B8: =Processing!B8 | C8: =Processing!R8 | D8: =IF(C8>=Parameters!$B$44,"HOT",IF(C8>=Parameters!$B$45,"WARM",IF(C8>=Parameters!$B$46,"NURTURE","DISQUALIFY"))) | E8: =IF('Raw Data'!P8>0,"Call",IF('Raw Data'!O8>0,"Email",IF('Raw Data'!N8>2,"LinkedIn","Cold Email"))) | F8: =IF(D8="HOT","Daily",IF(D8="WARM","2x/Week",IF(D8="NURTURE","Monthly","None"))) | G8: =IF('Raw Data'!P8=0,"Book intro call",IF('Raw Data'!O8=0,"Send follow-up","Schedule demo")) | H8: =TODAY()-'Raw Data'!Q8 | I8: ='Raw Data'!S8 | J8: =IF('Raw Data'!R8<>"","Discuss: "&'Raw Data'!R8,IF('Raw Data'!C8="SaaS","SaaS growth challenges",IF('Raw Data'!C8="FinTech","Compliance & scale","Efficiency gains")))
A9: =Processing!A9 | B9: =Processing!B9 | C9: =Processing!R9 | D9: =IF(C9>=Parameters!$B$44,"HOT",IF(C9>=Parameters!$B$45,"WARM",IF(C9>=Parameters!$B$46,"NURTURE","DISQUALIFY"))) | E9: =IF('Raw Data'!P9>0,"Call",IF('Raw Data'!O9>0,"Email",IF('Raw Data'!N9>2,"LinkedIn","Cold Email"))) | F9: =IF(D9="HOT","Daily",IF(D9="WARM","2x/Week",IF(D9="NURTURE","Monthly","None"))) | G9: =IF('Raw Data'!P9=0,"Book intro call",IF('Raw Data'!O9=0,"Send follow-up","Schedule demo")) | H9: =TODAY()-'Raw Data'!Q9 | I9: ='Raw Data'!S9 | J9: =IF('Raw Data'!R9<>"","Discuss: "&'Raw Data'!R9,IF('Raw Data'!C9="SaaS","SaaS growth challenges",IF('Raw Data'!C9="FinTech","Compliance & scale","Efficiency gains")))
A10: =Processing!A10 | B10: =Processing!B10 | C10: =Processing!R10 | D10: =IF(C10>=Parameters!$B$44,"HOT",IF(C10>=Parameters!$B$45,"WARM",IF(C10>=Parameters!$B$46,"NURTURE","DISQUALIFY"))) | E10: =IF('Raw Data'!P10>0,"Call",IF('Raw Data'!O10>0,"Email",IF('Raw Data'!N10>2,"LinkedIn","Cold Email"))) | F10: =IF(D10="HOT","Daily",IF(D10="WARM","2x/Week",IF(D10="NURTURE","Monthly","None"))) | G10: =IF('Raw Data'!P10=0,"Book intro call",IF('Raw Data'!O10=0,"Send follow-up","Schedule demo")) | H10: =TODAY()-'Raw Data'!Q10 | I10: ='Raw Data'!S10 | J10: =IF('Raw Data'!R10<>"","Discuss: "&'Raw Data'!R10,IF('Raw Data'!C10="SaaS","SaaS growth challenges",IF('Raw Data'!C10="FinTech","Compliance & scale","Efficiency gains")))
A11: =Processing!A11 | B11: =Processing!B11 | C11: =Processing!R11 | D11: =IF(C11>=Parameters!$B$44,"HOT",IF(C11>=Parameters!$B$45,"WARM",IF(C11>=Parameters!$B$46,"NURTURE","DISQUALIFY"))) | E11: =IF('Raw Data'!P11>0,"Call",IF('Raw Data'!O11>0,"Email",IF('Raw Data'!N11>2,"LinkedIn","Cold Email"))) | F11: =IF(D11="HOT","Daily",IF(D11="WARM","2x/Week",IF(D11="NURTURE","Monthly","None"))) | G11: =IF('Raw Data'!P11=0,"Book intro call",IF('Raw Data'!O11=0,"Send follow-up","Schedule demo")) | H11: =TODAY()-'Raw Data'!Q11 | I11: ='Raw Data'!S11 | J11: =IF('Raw Data'!R11<>"","Discuss: "&'Raw Data'!R11,IF('Raw Data'!C11="SaaS","SaaS growth challenges",IF('Raw Data'!C11="FinTech","Compliance & scale","Efficiency gains")))
A14: DASHBOARD METRICS
A15: Metric | B15: Value | C15: Formula
A16: Total Hot Prospects | B16: =COUNTIF(D2:D11,"HOT")
A17: Total Warm Prospects | B17: =COUNTIF(D2:D11,"WARM")
A18: Total Nurture | B18: =COUNTIF(D2:D11,"NURTURE")
A19: Total Disqualified | B19: =COUNTIF(D2:D11,"DISQUALIFY")
A20: Avg Score (Hot) | B20: =AVERAGEIF(D2:D11,"HOT",C2:C11)
A21: Avg Days Since Touch | B21: =AVERAGE(H2:H11)
A22: Stale Hot Prospects (>7 days) | B22: =SUMPRODUCT((D2:D11="HOT")*(H2:H11>7)) | C22: Needs attention
