Workbook
Name SafetyStockDays: Parameters!$B$5
Name DefaultLeadTime: Parameters!$B$6
Name ReorderMultiplier: Parameters!$B$7
Name MinOrderQty: Parameters!$B$8
Name MaxOrderQty: Parameters!$B$9
Name LowValueThreshold: Parameters!$B$12
Name HighValueThreshold: Parameters!$B$13
Name MaxOrderCost: Parameters!$B$14
Name MonthlyBudget: Parameters!$B$15
Name CriticalDays: Parameters!$B$18
Name WarningDays: Parameters!$B$19
Name OverstockDays: Parameters!$B$20
Name BulkThreshold: Parameters!$B$26
Name BulkDiscount: Parameters!$B$27

Sheet Parameters
A1: Inventory Reorder Parameters
A3: Parameter | B3: Value | C3: Description
A4: REORDER SETTINGS
A5: Safety Stock Days | B5: 7 | C5: Extra days of stock to maintain
A6: Default Lead Time (days) | B6: 5 | C6: Days to receive order if not specified
A7: Reorder Point Multiplier | B7: 1.2 | C7: Multiplier for reorder point calculation
A8: Min Order Quantity | B8: 10 | C8: Minimum units per order
A9: Max Order Quantity | B9: 500 | C9: Maximum units per order
A11: COST THRESHOLDS
A12: Low Value Threshold ($) | B12: 50 | C12: Items below this are low priority
A13: High Value Threshold ($) | B13: 500 | C13: Items above this need approval
A14: Max Single Order Cost ($) | B14: 10000 | C14: Alert if order exceeds this
A15: Monthly Budget ($) | B15: 50000 | C15: Monthly inventory budget
A17: ALERT SETTINGS
A18: Critical Stock Days | B18: 3 | C18: Alert if stock falls below this
A19: Warning Stock Days | B19: 7 | C19: Warning if stock falls below this
A20: Overstock Days | B20: 60 | C20: Flag if stock exceeds this many days
A21: Stockout Cost Multiplier | B21: 2.5 | C21: Cost factor for stockout risk
A23: SUPPLIER DEFAULTS
A24: Primary Supplier Lead Time | B24: 5 | C24: Default lead time for primary supplier
A25: Secondary Supplier Lead Time | B25: 7 | C25: Default lead time for backup supplier
A26: Express Shipping Premium (%) | B26: 50 | C26: Extra cost for expedited shipping
A27: Bulk Discount Threshold (units) | B27: 100 | C27: Quantity for bulk discount
A28: Bulk Discount Rate (%) | B28: 10 | C28: Discount percentage for bulk orders

Sheet Inventory
A1: Inventory Data - Raw Input
A3: SKU | B3: Product Name | C3: Category | D3: Current Stock | E3: Daily Sales Rate | F3: Unit Cost ($) | G3: Selling Price ($) | H3: Supplier | I3: Lead Time (days) | J3: Min Stock Level | K3: Max Stock Level | L3: Last Restock Date | M3: Last Order Qty | N3: Notes
A4: EL-001 | B4: USB Cable Type-C | C4: Electronics | D4: 7 | E4: 23.5 | F4: 50.98 | G4: 96.2 | H4: Acme Corp | I4: 9 | J4: 164 | K4: 1057 | L4: 2026-01-18 | M4: 193 | N4: New supplier
A5: EL-002 | B5: Wireless Mouse | C5: Electronics | D5: 24 | E5: 11.4 | F5: 60.06 | G5: 88.39 | H5: Acme Corp | I5: 9 | J5: 79 | K5: 513 | L5: 2026-01-03 | M5: 146
A6: EL-003 | B6: HDMI Adapter | C6: Electronics | D6: 19 | E6: 4.9 | F6: 20.92 | G6: 36.97 | H6: Global Supply | I6: 3 | J6: 34 | K6: 220 | L6: 2026-01-10 | M6: 160
A7: EL-004 | B7: Power Bank 10000mAh | C7: Electronics | D7: 246 | E7: 10.5 | F7: 85.43 | G7: 139.94 | H7: Direct Source | I7: 8 | J7: 73 | K7: 472 | L7: 2026-01-01 | M7: 151 | N7: Price increase pending
A8: EL-005 | B8: Bluetooth Speaker | C8: Electronics | D8: 220 | E8: 18.7 | F8: 127.52 | G8: 212.25 | H8: Wholesale Plus | I8: 8 | J8: 130 | K8: 841 | L8: 2026-01-17 | M8: 58
A9: EL-006 | B9: Webcam HD | C9: Electronics | D9: 35 | E9: 20.4 | F9: 37.97 | G9: 58.32 | H9: Wholesale Plus | I9: 4 | J9: 142 | K9: 917 | L9: 2026-01-15 | M9: 149 | N9: New supplier
A10: OS-001 | B10: A4 Paper Ream | C10: Office Supplies | D10: 7 | E10: 25.3 | F10: 20.09 | G10: 38.72 | H10: Global Supply | I10: 9 | J10: 177 | K10: 1138 | L10: 2026-01-18 | M10: 178
A11: OS-002 | B11: Ballpoint Pens (box) | C11: Office Supplies | D11: 296 | E11: 23.4 | F11: 36.85 | G11: 61.94 | H11: Global Supply | I11: 5 | J11: 163 | K11: 1053 | L11: 2026-01-18 | M11: 163 | N11: Price increase pending
A12: OS-003 | B12: Sticky Notes Pack | C12: Office Supplies | D12: 24 | E12: 14.8 | F12: 3.99 | G12: 7.42 | H12: FastShip Inc | I12: 9 | J12: 103 | K12: 666 | L12: 2026-01-14 | M12: 50
A13: OS-004 | B13: Stapler | C13: Office Supplies | D13: 231 | E13: 4.5 | F13: 23.36 | G13: 30.51 | H13: Direct Source | I13: 9 | J13: 31 | K13: 202 | L13: 2026-01-03 | M13: 189 | N13: Price increase pending
A14: OS-005 | B14: Binder Clips (box) | C14: Office Supplies | D14: 15 | E14: 9.4 | F14: 25.21 | G14: 46.02 | H14: FastShip Inc | I14: 9 | J14: 65 | K14: 423 | L14: 2026-01-12 | M14: 56
A15: OS-006 | B15: Whiteboard Markers | C15: Office Supplies | D15: 233 | E15: 26.4 | F15: 9.77 | G15: 17.27 | H15: Acme Corp | I15: 3 | J15: 184 | K15: 1188 | L15: 2026-01-17 | M15: 149 | N15: Seasonal
A16: FU-001 | B16: Office Chair | C16: Furniture | D16: 14 | E16: 23.7 | F16: 255.7 | G16: 355.05 | H16: FastShip Inc | I16: 4 | J16: 165 | K16: 1066 | L16: 2026-01-06 | M16: 200 | N16: Price increase pending
A17: FU-002 | B17: Standing Desk | C17: Furniture | D17: 166 | E17: 20.7 | F17: 239.82 | G17: 458 | H17: Wholesale Plus | I17: 7 | J17: 144 | K17: 931 | L17: 2026-01-14 | M17: 57
A18: FU-003 | B18: Filing Cabinet | C18: Furniture | D18: 181 | E18: 17.6 | F18: 237.43 | G18: 326.07 | H18: FastShip Inc | I18: 6 | J18: 123 | K18: 792 | L18: 2026-01-19 | M18: 137
A19: FU-004 | B19: Bookshelf | C19: Furniture | D19: 102 | E19: 26.8 | F19: 205.82 | G19: 273.76 | H19: Direct Source | I19: 4 | J19: 187 | K19: 1206 | L19: 2026-01-07 | M19: 179 | N19: Popular item
A20: TL-001 | B20: Screwdriver Set | C20: Tools | D20: 54 | E20: 7.4 | F20: 29.54 | G20: 40.16 | H20: FastShip Inc | I20: 4 | J20: 51 | K20: 333 | L20: 2026-01-11 | M20: 191
A21: TL-002 | B21: Drill Bits Pack | C21: Tools | D21: 186 | E21: 5.8 | F21: 45.39 | G21: 74.65 | H21: Wholesale Plus | I21: 3 | J21: 40 | K21: 261 | L21: 2026-01-09 | M21: 197
A22: TL-003 | B22: Measuring Tape | C22: Tools | D22: 265 | E22: 16 | F22: 8.93 | G22: 15.58 | H22: Direct Source | I22: 10 | J22: 112 | K22: 720 | L22: 2026-01-11 | M22: 199
A23: TL-004 | B23: Safety Goggles | C23: Tools | D23: 167 | E23: 12.1 | F23: 34.44 | G23: 54.92 | H23: FastShip Inc | I23: 6 | J23: 84 | K23: 544 | L23: 2026-01-15 | M23: 137 | N23: Popular item
A24: TL-005 | B24: Work Gloves (pair) | C24: Tools | D24: 45 | E24: 3.7 | F24: 22.49 | G24: 37.12 | H24: Global Supply | I24: 9 | J24: 25 | K24: 166 | L24: 2026-01-12 | M24: 67 | N24: Seasonal
A25: PK-001 | B25: Shipping Boxes Small | C25: Packaging | D25: 13 | E25: 16.1 | F25: 31.46 | G25: 42.11 | H25: Wholesale Plus | I25: 3 | J25: 112 | K25: 724 | L25: 2026-01-19 | M25: 149 | N25: Seasonal
A26: PK-002 | B26: Shipping Boxes Medium | C26: Packaging | D26: 15 | E26: 8.8 | F26: 23.93 | G26: 45.19 | H26: Direct Source | I26: 8 | J26: 61 | K26: 396 | L26: 2026-01-08 | M26: 166 | N26: Seasonal
A27: PK-003 | B27: Shipping Boxes Large | C27: Packaging | D27: 23 | E27: 2.6 | F27: 34.03 | G27: 61.72 | H27: Wholesale Plus | I27: 3 | J27: 18 | K27: 117 | L27: 2026-01-16 | M27: 188
A28: PK-004 | B28: Bubble Wrap Roll | C28: Packaging | D28: 291 | E28: 8.2 | F28: 43.61 | G28: 70.84 | H28: Direct Source | I28: 7 | J28: 57 | K28: 368 | L28: 2026-01-19 | M28: 53 | N28: New supplier
A29: PK-005 | B29: Packing Tape | C29: Packaging | D29: 48 | E29: 3.8 | F29: 14.91 | G29: 21.14 | H29: Wholesale Plus | I29: 8 | J29: 26 | K29: 171 | L29: 2026-01-14 | M29: 61
A30: PK-006 | B30: Shipping Labels (roll) | C30: Packaging | D30: 21 | E30: 9.5 | F30: 10.8 | G30: 19.61 | H30: Direct Source | I30: 6 | J30: 66 | K30: 427 | L30: 2026-01-10 | M30: 177
A31: PK-007 | B31: Foam Peanuts (bag) | C31: Packaging | D31: 76 | E31: 14.4 | F31: 28.61 | G31: 42.79 | H31: Global Supply | I31: 4 | J31: 100 | K31: 648 | L31: 2026-01-13 | M31: 154
A32: EL-007 | B32: USB Hub 4-Port | C32: Electronics | D32: 18 | E32: 23.3 | F32: 73.86 | G32: 114.45 | H32: Wholesale Plus | I32: 5 | J32: 163 | K32: 1048 | L32: 2026-01-07 | M32: 104 | N32: Popular item
A33: OS-007 | B33: Desk Organizer | C33: Office Supplies | D33: 26 | E33: 4.1 | F33: 46.58 | G33: 60.91 | H33: FastShip Inc | I33: 3 | J33: 28 | K33: 184 | L33: 2026-01-02 | M33: 113 | N33: Price increase pending

Sheet Analysis
A1: Inventory Analysis - Calculated Metrics
A3: SKU | B3: Product Name | C3: Current Stock | D3: Daily Sales | E3: Days of Stock | F3: Reorder Point | G3: Below Reorder? | H3: Qty to Order | I3: Order Cost ($) | J3: Stock Status | K3: Priority Score | L3: Value Category | M3: Stockout Risk ($) | N3: Supplier | O3: Lead Time | P3: Est. Arrival
A4: =Inventory!A4 | B4: =Inventory!B4 | C4: =Inventory!D4 | D4: =Inventory!E4 | E4: =IF(D4>0,ROUND(C4/D4,1),999) | F4: =ROUND((D4*(Inventory!I4+SafetyStockDays))*ReorderMultiplier,0) | G4: =IF(C4<=F4,"YES","No") | H4: =IF(G4="YES",MIN(MaxOrderQty,MAX(MinOrderQty,F4+D4*SafetyStockDays-C4)),0) | I4: =IF(H4>=BulkThreshold,H4*Inventory!F4*(1-BulkDiscount/100),H4*Inventory!F4) | J4: =IF(E4<=CriticalDays,"CRITICAL",IF(E4<=WarningDays,"WARNING",IF(E4>=OverstockDays,"OVERSTOCK","OK"))) | K4: =IF(G4="YES",ROUND((F4-C4)/F4*100+IF(Inventory!F4>HighValueThreshold,20,0),0),0) | L4: =IF(Inventory!F4>=HighValueThreshold,"High",IF(Inventory!F4>=LowValueThreshold,"Medium","Low")) | M4: =IF(E4<Inventory!I4,ROUND((Inventory!I4-E4)*D4*Inventory!G4*2.5,0),0) | N4: =Inventory!H4 | O4: =Inventory!I4 | P4: =IF(G4="YES",TODAY()+O4,"")
A5: =Inventory!A5 | B5: =Inventory!B5 | C5: =Inventory!D5 | D5: =Inventory!E5 | E5: =IF(D5>0,ROUND(C5/D5,1),999) | F5: =ROUND((D5*(Inventory!I5+SafetyStockDays))*ReorderMultiplier,0) | G5: =IF(C5<=F5,"YES","No") | H5: =IF(G5="YES",MIN(MaxOrderQty,MAX(MinOrderQty,F5+D5*SafetyStockDays-C5)),0) | I5: =IF(H5>=BulkThreshold,H5*Inventory!F5*(1-BulkDiscount/100),H5*Inventory!F5) | J5: =IF(E5<=CriticalDays,"CRITICAL",IF(E5<=WarningDays,"WARNING",IF(E5>=OverstockDays,"OVERSTOCK","OK"))) | K5: =IF(G5="YES",ROUND((F5-C5)/F5*100+IF(Inventory!F5>HighValueThreshold,20,0),0),0) | L5: =IF(Inventory!F5>=HighValueThreshold,"High",IF(Inventory!F5>=LowValueThreshold,"Medium","Low")) | M5: =IF(E5<Inventory!I5,ROUND((Inventory!I5-E5)*D5*Inventory!G5*2.5,0),0) | N5: =Inventory!H5 | O5: =Inventory!I5 | P5: =IF(G5="YES",TODAY()+O5,"")
A6: =Inventory!A6 | B6: =Inventory!B6 | C6: =Inventory!D6 | D6: =Inventory!E6 | E6: =IF(D6>0,ROUND(C6/D6,1),999) | F6: =ROUND((D6*(Inventory!I6+SafetyStockDays))*ReorderMultiplier,0) | G6: =IF(C6<=F6,"YES","No") | H6: =IF(G6="YES",MIN(MaxOrderQty,MAX(MinOrderQty,F6+D6*SafetyStockDays-C6)),0) | I6: =IF(H6>=BulkThreshold,H6*Inventory!F6*(1-BulkDiscount/100),H6*Inventory!F6) | J6: =IF(E6<=CriticalDays,"CRITICAL",IF(E6<=WarningDays,"WARNING",IF(E6>=OverstockDays,"OVERSTOCK","OK"))) | K6: =IF(G6="YES",ROUND((F6-C6)/F6*100+IF(Inventory!F6>HighValueThreshold,20,0),0),0) | L6: =IF(Inventory!F6>=HighValueThreshold,"High",IF(Inventory!F6>=LowValueThreshold,"Medium","Low")) | M6: =IF(E6<Inventory!I6,ROUND((Inventory!I6-E6)*D6*Inventory!G6*2.5,0),0) | N6: =Inventory!H6 | O6: =Inventory!I6 | P6: =IF(G6="YES",TODAY()+O6,"")
A7: =Inventory!A7 | B7: =Inventory!B7 | C7: =Inventory!D7 | D7: =Inventory!E7 | E7: =IF(D7>0,ROUND(C7/D7,1),999) | F7: =ROUND((D7*(Inventory!I7+SafetyStockDays))*ReorderMultiplier,0) | G7: =IF(C7<=F7,"YES","No") | H7: =IF(G7="YES",MIN(MaxOrderQty,MAX(MinOrderQty,F7+D7*SafetyStockDays-C7)),0) | I7: =IF(H7>=BulkThreshold,H7*Inventory!F7*(1-BulkDiscount/100),H7*Inventory!F7) | J7: =IF(E7<=CriticalDays,"CRITICAL",IF(E7<=WarningDays,"WARNING",IF(E7>=OverstockDays,"OVERSTOCK","OK"))) | K7: =IF(G7="YES",ROUND((F7-C7)/F7*100+IF(Inventory!F7>HighValueThreshold,20,0),0),0) | L7: =IF(Inventory!F7>=HighValueThreshold,"High",IF(Inventory!F7>=LowValueThreshold,"Medium","Low")) | M7: =IF(E7<Inventory!I7,ROUND((Inventory!I7-E7)*D7*Inventory!G7*2.5,0),0) | N7: =Inventory!H7 | O7: =Inventory!I7 | P7: =IF(G7="YES",TODAY()+O7,"")
A8: =Inventory!A8 | B8: =Inventory!B8 | C8: =Inventory!D8 | D8: =Inventory!E8 | E8: =IF(D8>0,ROUND(C8/D8,1),999) | F8: =ROUND((D8*(Inventory!I8+SafetyStockDays))*ReorderMultiplier,0) | G8: =IF(C8<=F8,"YES","No") | H8: =IF(G8="YES",MIN(MaxOrderQty,MAX(MinOrderQty,F8+D8*SafetyStockDays-C8)),0) | I8: =IF(H8>=BulkThreshold,H8*Inventory!F8*(1-BulkDiscount/100),H8*Inventory!F8) | J8: =IF(E8<=CriticalDays,"CRITICAL",IF(E8<=WarningDays,"WARNING",IF(E8>=OverstockDays,"OVERSTOCK","OK"))) | K8: =IF(G8="YES",ROUND((F8-C8)/F8*100+IF(Inventory!F8>HighValueThreshold,20,0),0),0) | L8: =IF(Inventory!F8>=HighValueThreshold,"High",IF(Inventory!F8>=LowValueThreshold,"Medium","Low")) | M8: =IF(E8<Inventory!I8,ROUND((Inventory!I8-E8)*D8*Inventory!G8*2.5,0),0) | N8: =Inventory!H8 | O8: =Inventory!I8 | P8: =IF(G8="YES",TODAY()+O8,"")
A9: =Inventory!A9 | B9: =Inventory!B9 | C9: =Inventory!D9 | D9: =Inventory!E9 | E9: =IF(D9>0,ROUND(C9/D9,1),999) | F9: =ROUND((D9*(Inventory!I9+SafetyStockDays))*ReorderMultiplier,0) | G9: =IF(C9<=F9,"YES","No") | H9: =IF(G9="YES",MIN(MaxOrderQty,MAX(MinOrderQty,F9+D9*SafetyStockDays-C9)),0) | I9: =IF(H9>=BulkThreshold,H9*Inventory!F9*(1-BulkDiscount/100),H9*Inventory!F9) | J9: =IF(E9<=CriticalDays,"CRITICAL",IF(E9<=WarningDays,"WARNING",IF(E9>=OverstockDays,"OVERSTOCK","OK"))) | K9: =IF(G9="YES",ROUND((F9-C9)/F9*100+IF(Inventory!F9>HighValueThreshold,20,0),0),0) | L9: =IF(Inventory!F9>=HighValueThreshold,"High",IF(Inventory!F9>=LowValueThreshold,"Medium","Low")) | M9: =IF(E9<Inventory!I9,ROUND((Inventory!I9-E9)*D9*Inventory!G9*2.5,0),0) | N9: =Inventory!H9 | O9: =Inventory!I9 | P9: =IF(G9="YES",TODAY()+O9,"")
A10: =Inventory!A10 | B10: =Inventory!B10 | C10: =Inventory!D10 | D10: =Inventory!E10 | E10: =IF(D10>0,ROUND(C10/D10,1),999) | F10: =ROUND((D10*(Inventory!I10+SafetyStockDays))*ReorderMultiplier,0) | G10: =IF(C10<=F10,"YES","No") | H10: =IF(G10="YES",MIN(MaxOrderQty,MAX(MinOrderQty,F10+D10*SafetyStockDays-C10)),0) | I10: =IF(H10>=BulkThreshold,H10*Inventory!F10*(1-BulkDiscount/100),H10*Inventory!F10) | J10: =IF(E10<=CriticalDays,"CRITICAL",IF(E10<=WarningDays,"WARNING",IF(E10>=OverstockDays,"OVERSTOCK","OK"))) | K10: =IF(G10="YES",ROUND((F10-C10)/F10*100+IF(Inventory!F10>HighValueThreshold,20,0),0),0) | L10: =IF(Inventory!F10>=HighValueThreshold,"High",IF(Inventory!F10>=LowValueThreshold,"Medium","Low")) | M10: =IF(E10<Inventory!I10,ROUND((Inventory!I10-E10)*D10*Inventory!G10*2.5,0),0) | N10: =Inventory!H10 | O10: =Inventory!I10 | P10: =IF(G10="YES",TODAY()+O10,"")
A11: =Inventory!A11 | B11: =Inventory!B11 | C11: =Inventory!D11 | D11: =Inventory!E11 | E11: =IF(D11>0,ROUND(C11/D11,1),999) | F11: =ROUND((D11*(Inventory!I11+SafetyStockDays))*ReorderMultiplier,0) | G11: =IF(C11<=F11,"YES","No") | H11: =IF(G11="YES",MIN(MaxOrderQty,MAX(MinOrderQty,F11+D11*SafetyStockDays-C11)),0) | I11: =IF(H11>=BulkThreshold,H11*Inventory!F11*(1-BulkDiscount/100),H11*Inventory!F11) | J11: =IF(E11<=CriticalDays,"CRITICAL",IF(E11<=WarningDays,"WARNING",IF(E11>=OverstockDays,"OVERSTOCK","OK"))) | K11: =IF(G11="YES",ROUND((F11-C11)/F11*100+IF(Inventory!F11>HighValueThreshold,20,0),0),0) | L11: =IF(Inventory!F11>=HighValueThreshold,"High",IF(Inventory!F11>=LowValueThreshold,"Medium","Low")) | M11: =IF(E11<Inventory!I11,ROUND((Inventory!I11-E11)*D11*Inventory!G11*2.5,0),0) | N11: =Inventory!H11 | O11: =Inventory!I11 | P11: =IF(G11="YES",TODAY()+O11,"")
A12: =Inventory!A12 | B12: =Inventory!B12 | C12: =Inventory!D12 | D12: =Inventory!E12 | E12: =IF(D12>0,ROUND(C12/D12,1),999) | F12: =ROUND((D12*(Inventory!I12+SafetyStockDays))*ReorderMultiplier,0) | G12: =IF(C12<=F12,"YES","No") | H12: =IF(G12="YES",MIN(MaxOrderQty,MAX(MinOrderQty,F12+D12*SafetyStockDays-C12)),0) | I12: =IF(H12>=BulkThreshold,H12*Inventory!F12*(1-BulkDiscount/100),H12*Inventory!F12) | J12: =IF(E12<=CriticalDays,"CRITICAL",IF(E12<=WarningDays,"WARNING",IF(E12>=OverstockDays,"OVERSTOCK","OK"))) | K12: =IF(G12="YES",ROUND((F12-C12)/F12*100+IF(Inventory!F12>HighValueThreshold,20,0),0),0) | L12: =IF(Inventory!F12>=HighValueThreshold,"High",IF(Inventory!F12>=LowValueThreshold,"Medium","Low")) | M12: =IF(E12<Inventory!I12,ROUND((Inventory!I12-E12)*D12*Inventory!G12*2.5,0),0) | N12: =Inventory!H12 | O12: =Inventory!I12 | P12: =IF(G12="YES",TODAY()+O12,"")
A13: =Inventory!A13 | B13: =Inventory!B13 | C13: =Inventory!D13 | D13: =Inventory!E13 | E13: =IF(D13>0,ROUND(C13/D13,1),999) | F13: =ROUND((D13*(Inventory!I13+SafetyStockDays))*ReorderMultiplier,0) | G13: =IF(C13<=F13,"YES","No") | H13: =IF(G13="YES",MIN(MaxOrderQty,MAX(MinOrderQty,F13+D13*SafetyStockDays-C13)),0) | I13: =IF(H13>=BulkThreshold,H13*Inventory!F13*(1-BulkDiscount/100),H13*Inventory!F13) | J13: =IF(E13<=CriticalDays,"CRITICAL",IF(E13<=WarningDays,"WARNING",IF(E13>=OverstockDays,"OVERSTOCK","OK"))) | K13: =IF(G13="YES",ROUND((F13-C13)/F13*100+IF(Inventory!F13>HighValueThreshold,20,0),0),0) | L13: =IF(Inventory!F13>=HighValueThreshold,"High",IF(Inventory!F13>=LowValueThreshold,"Medium","Low")) | M13: =IF(E13<Inventory!I13,ROUND((Inventory!I13-E13)*D13*Inventory!G13*2.5,0),0) | N13: =Inventory!H13 | O13: =Inventory!I13 | P13: =IF(G13="YES",TODAY()+O13,"")
A14: =Inventory!A14 | B14: =Inventory!B14 | C14: =Inventory!D14 | D14: =Inventory!E14 | E14: =IF(D14>0,ROUND(C14/D14,1),999) | F14: =ROUND((D14*(Inventory!I14+SafetyStockDays))*ReorderMultiplier,0) | G14: =IF(C14<=F14,"YES","No") | H14: =IF(G14="YES",MIN(MaxOrderQty,MAX(MinOrderQty,F14+D14*SafetyStockDays-C14)),0) | I14: =IF(H14>=BulkThreshold,H14*Inventory!F14*(1-BulkDiscount/100),H14*Inventory!F14) | J14: =IF(E14<=CriticalDays,"CRITICAL",IF(E14<=WarningDays,"WARNING",IF(E14>=OverstockDays,"OVERSTOCK","OK"))) | K14: =IF(G14="YES",ROUND((F14-C14)/F14*100+IF(Inventory!F14>HighValueThreshold,20,0),0),0) | L14: =IF(Inventory!F14>=HighValueThreshold,"High",IF(Inventory!F14>=LowValueThreshold,"Medium","Low")) | M14: =IF(E14<Inventory!I14,ROUND((Inventory!I14-E14)*D14*Inventory!G14*2.5,0),0) | N14: =Inventory!H14 | O14: =Inventory!I14 | P14: =IF(G14="YES",TODAY()+O14,"")
A15: =Inventory!A15 | B15: =Inventory!B15 | C15: =Inventory!D15 | D15: =Inventory!E15 | E15: =IF(D15>0,ROUND(C15/D15,1),999) | F15: =ROUND((D15*(Inventory!I15+SafetyStockDays))*ReorderMultiplier,0) | G15: =IF(C15<=F15,"YES","No") | H15: =IF(G15="YES",MIN(MaxOrderQty,MAX(MinOrderQty,F15+D15*SafetyStockDays-C15)),0) | I15: =IF(H15>=BulkThreshold,H15*Inventory!F15*(1-BulkDiscount/100),H15*Inventory!F15) | J15: =IF(E15<=CriticalDays,"CRITICAL",IF(E15<=WarningDays,"WARNING",IF(E15>=OverstockDays,"OVERSTOCK","OK"))) | K15: =IF(G15="YES",ROUND((F15-C15)/F15*100+IF(Inventory!F15>HighValueThreshold,20,0),0),0) | L15: =IF(Inventory!F15>=HighValueThreshold,"High",IF(Inventory!F15>=LowValueThreshold,"Medium","Low")) | M15: =IF(E15<Inventory!I15,ROUND((Inventory!I15-E15)*D15*Inventory!G15*2.5,0),0) | N15: =Inventory!H15 | O15: =Inventory!I15 | P15: =IF(G15="YES",TODAY()+O15,"")
... A33: =Inventory!A33 | B33: =Inventory!B33 | C33: =Inventory!D33 | D33: =Inventory!E33 | E33: =IF(D33>0,ROUND(C33/D33,1),999) | F33: =ROUND((D33*(Inventory!I33+SafetyStockDays))*ReorderMultiplier,0) | G33: =IF(C33<=F33,"YES","No") | H33: =IF(G33="YES",MIN(MaxOrderQty,MAX(MinOrderQty,F33+D33*SafetyStockDays-C33)),0) | I33: =IF(H33>=BulkThreshold,H33*Inventory!F33*(1-BulkDiscount/100),H33*Inventory!F33) | J33: =IF(E33<=CriticalDays,"CRITICAL",IF(E33<=WarningDays,"WARNING",IF(E33>=OverstockDays,"OVERSTOCK","OK"))) | K33: =IF(G33="YES",ROUND((F33-C33)/F33*100+IF(Inventory!F33>HighValueThreshold,20,0),0),0) | L33: =IF(Inventory!F33>=HighValueThreshold,"High",IF(Inventory!F33>=LowValueThreshold,"Medium","Low")) | M33: =IF(E33<Inventory!I33,ROUND((Inventory!I33-E33)*D33*Inventory!G33*2.5,0),0) | N33: =Inventory!H33 | O33: =Inventory!I33 | P33: =IF(G33="YES",TODAY()+O33,"")

Sheet Reorder Decisions
A1: Inventory Reorder Decisions
A3: INVENTORY SUMMARY | D3: RISK ASSESSMENT
A4: Total SKUs | B4: =COUNTA(Analysis!A:A)-1 | D4: Total Stockout Risk ($) | E4: =SUM(Analysis!M:M)
A5: Items Below Reorder Point | B5: =COUNTIF(Analysis!G:G,"YES") | D5: Highest Risk Item | E5: =INDEX(Analysis!B:B,MATCH(MAX(Analysis!M:M),Analysis!M:M,0))
A6: Critical Stock Items | B6: =COUNTIF(Analysis!J:J,"CRITICAL") | D6: Highest Risk Amount ($) | E6: =MAX(Analysis!M:M)
A7: Warning Stock Items | B7: =COUNTIF(Analysis!J:J,"WARNING") | D7: Items at Stockout Risk | E7: =COUNTIF(Analysis!M:M,">0")
A8: Overstock Items | B8: =COUNTIF(Analysis!J:J,"OVERSTOCK") | D8: Avg Lead Time (days) | E8: =AVERAGEIF(Analysis!O:O,">0")
A9: Items OK | B9: =COUNTIF(Analysis!J:J,"OK") | D9: Longest Lead Time (days) | E9: =MAX(Analysis!O:O)
A10: Total Inventory Value ($) | B10: =SUMPRODUCT(Inventory!D4:D33,Inventory!F4:F33)
A11: Avg Days of Stock | B11: =AVERAGEIF(Analysis!E:E,"<999") | D11: DECISION
D12: Action Required | E12: =IF(B6>0,"IMMEDIATE REORDER NEEDED",IF(B7>0,"MONITOR CLOSELY","INVENTORY HEALTHY"))
A13: REORDER RECOMMENDATIONS | D13: Priority Level | E13: =IF(B6>3,"HIGH",IF(B6>0,"MEDIUM",IF(B7>5,"LOW","NONE")))
A14: Items to Reorder Now | B14: =COUNTIF(Analysis!G:G,"YES") | D14: Budget Status | E14: =IF(B28="No","Within Budget","OVER BUDGET")
A15: Total Units to Order | B15: =SUMIF(Analysis!G:G,"YES",Analysis!H:H)
A16: Total Reorder Cost ($) | B16: =SUMIF(Analysis!G:G,"YES",Analysis!I:I)
A17: High Priority Orders | B17: =COUNTIFS(Analysis!G:G,"YES",Analysis!K:K,">=50")
A18: High Value Orders | B18: =COUNTIFS(Analysis!G:G,"YES",Analysis!L:L,"High")
A19: Orders Qualifying for Bulk Discount | B19: =COUNTIFS(Analysis!G:G,"YES",Analysis!H:H,">="&BulkThreshold)
A20: Estimated Bulk Savings ($) | B20: =SUMPRODUCT((Analysis!G4:G33="YES")*(Analysis!H4:H33>=BulkThreshold)*(Analysis!H4:H33)*(Inventory!F4:F33)*(BulkDiscount/100))
A22: BUDGET ANALYSIS
A23: Monthly Budget ($) | B23: =MonthlyBudget
A24: Total Reorder Cost ($) | B24: =B15
A25: Remaining Budget ($) | B25: =B24-B25
A26: Budget Utilization (%) | B26: =B25/B24
A27: Over Budget? | B27: =IF(B25>B24,"YES - REVIEW ORDERS","No")
A28: Orders Exceeding Max ($) | B28: =COUNTIFS(Analysis!G:G,"YES",Analysis!I:I,">"&MaxOrderCost)
A32: ITEMS TO REORDER (Sorted by Priority)
A33: SKU | B33: Product | C33: Current Stock | D33: Reorder Point | E33: Qty to Order | F33: Order Cost | G33: Priority
A34: =IFERROR(INDEX(Analysis!A:A,SMALL(IF(Analysis!G:G="YES",ROW(Analysis!G:G)),1)),"") | B34: =IF(A34<>"",INDEX(Analysis!B:B,MATCH(A34,Analysis!A:A,0)),"") | C34: =IF(A34<>"",INDEX(Analysis!C:C,MATCH(A34,Analysis!A:A,0)),"") | D34: =IF(A34<>"",INDEX(Analysis!F:F,MATCH(A34,Analysis!A:A,0)),"") | E34: =IF(A34<>"",INDEX(Analysis!H:H,MATCH(A34,Analysis!A:A,0)),"") | F34: =IF(A34<>"",INDEX(Analysis!I:I,MATCH(A34,Analysis!A:A,0)),"") | G34: =IF(A34<>"",INDEX(Analysis!K:K,MATCH(A34,Analysis!A:A,0)),"")
A35: =IFERROR(INDEX(Analysis!A:A,SMALL(IF(Analysis!G:G="YES",ROW(Analysis!G:G)),2)),"") | B35: =IF(A35<>"",INDEX(Analysis!B:B,MATCH(A35,Analysis!A:A,0)),"") | C35: =IF(A35<>"",INDEX(Analysis!C:C,MATCH(A35,Analysis!A:A,0)),"") | D35: =IF(A35<>"",INDEX(Analysis!F:F,MATCH(A35,Analysis!A:A,0)),"") | E35: =IF(A35<>"",INDEX(Analysis!H:H,MATCH(A35,Analysis!A:A,0)),"") | F35: =IF(A35<>"",INDEX(Analysis!I:I,MATCH(A35,Analysis!A:A,0)),"") | G35: =IF(A35<>"",INDEX(Analysis!K:K,MATCH(A35,Analysis!A:A,0)),"")
A36: =IFERROR(INDEX(Analysis!A:A,SMALL(IF(Analysis!G:G="YES",ROW(Analysis!G:G)),3)),"") | B36: =IF(A36<>"",INDEX(Analysis!B:B,MATCH(A36,Analysis!A:A,0)),"") | C36: =IF(A36<>"",INDEX(Analysis!C:C,MATCH(A36,Analysis!A:A,0)),"") | D36: =IF(A36<>"",INDEX(Analysis!F:F,MATCH(A36,Analysis!A:A,0)),"") | E36: =IF(A36<>"",INDEX(Analysis!H:H,MATCH(A36,Analysis!A:A,0)),"") | F36: =IF(A36<>"",INDEX(Analysis!I:I,MATCH(A36,Analysis!A:A,0)),"") | G36: =IF(A36<>"",INDEX(Analysis!K:K,MATCH(A36,Analysis!A:A,0)),"")
A37: =IFERROR(INDEX(Analysis!A:A,SMALL(IF(Analysis!G:G="YES",ROW(Analysis!G:G)),4)),"") | B37: =IF(A37<>"",INDEX(Analysis!B:B,MATCH(A37,Analysis!A:A,0)),"") | C37: =IF(A37<>"",INDEX(Analysis!C:C,MATCH(A37,Analysis!A:A,0)),"") | D37: =IF(A37<>"",INDEX(Analysis!F:F,MATCH(A37,Analysis!A:A,0)),"") | E37: =IF(A37<>"",INDEX(Analysis!H:H,MATCH(A37,Analysis!A:A,0)),"") | F37: =IF(A37<>"",INDEX(Analysis!I:I,MATCH(A37,Analysis!A:A,0)),"") | G37: =IF(A37<>"",INDEX(Analysis!K:K,MATCH(A37,Analysis!A:A,0)),"")
A38: =IFERROR(INDEX(Analysis!A:A,SMALL(IF(Analysis!G:G="YES",ROW(Analysis!G:G)),5)),"") | B38: =IF(A38<>"",INDEX(Analysis!B:B,MATCH(A38,Analysis!A:A,0)),"") | C38: =IF(A38<>"",INDEX(Analysis!C:C,MATCH(A38,Analysis!A:A,0)),"") | D38: =IF(A38<>"",INDEX(Analysis!F:F,MATCH(A38,Analysis!A:A,0)),"") | E38: =IF(A38<>"",INDEX(Analysis!H:H,MATCH(A38,Analysis!A:A,0)),"") | F38: =IF(A38<>"",INDEX(Analysis!I:I,MATCH(A38,Analysis!A:A,0)),"") | G38: =IF(A38<>"",INDEX(Analysis!K:K,MATCH(A38,Analysis!A:A,0)),"")
A39: =IFERROR(INDEX(Analysis!A:A,SMALL(IF(Analysis!G:G="YES",ROW(Analysis!G:G)),6)),"") | B39: =IF(A39<>"",INDEX(Analysis!B:B,MATCH(A39,Analysis!A:A,0)),"") | C39: =IF(A39<>"",INDEX(Analysis!C:C,MATCH(A39,Analysis!A:A,0)),"") | D39: =IF(A39<>"",INDEX(Analysis!F:F,MATCH(A39,Analysis!A:A,0)),"") | E39: =IF(A39<>"",INDEX(Analysis!H:H,MATCH(A39,Analysis!A:A,0)),"") | F39: =IF(A39<>"",INDEX(Analysis!I:I,MATCH(A39,Analysis!A:A,0)),"") | G39: =IF(A39<>"",INDEX(Analysis!K:K,MATCH(A39,Analysis!A:A,0)),"")
A40: =IFERROR(INDEX(Analysis!A:A,SMALL(IF(Analysis!G:G="YES",ROW(Analysis!G:G)),7)),"") | B40: =IF(A40<>"",INDEX(Analysis!B:B,MATCH(A40,Analysis!A:A,0)),"") | C40: =IF(A40<>"",INDEX(Analysis!C:C,MATCH(A40,Analysis!A:A,0)),"") | D40: =IF(A40<>"",INDEX(Analysis!F:F,MATCH(A40,Analysis!A:A,0)),"") | E40: =IF(A40<>"",INDEX(Analysis!H:H,MATCH(A40,Analysis!A:A,0)),"") | F40: =IF(A40<>"",INDEX(Analysis!I:I,MATCH(A40,Analysis!A:A,0)),"") | G40: =IF(A40<>"",INDEX(Analysis!K:K,MATCH(A40,Analysis!A:A,0)),"")
A41: =IFERROR(INDEX(Analysis!A:A,SMALL(IF(Analysis!G:G="YES",ROW(Analysis!G:G)),8)),"") | B41: =IF(A41<>"",INDEX(Analysis!B:B,MATCH(A41,Analysis!A:A,0)),"") | C41: =IF(A41<>"",INDEX(Analysis!C:C,MATCH(A41,Analysis!A:A,0)),"") | D41: =IF(A41<>"",INDEX(Analysis!F:F,MATCH(A41,Analysis!A:A,0)),"") | E41: =IF(A41<>"",INDEX(Analysis!H:H,MATCH(A41,Analysis!A:A,0)),"") | F41: =IF(A41<>"",INDEX(Analysis!I:I,MATCH(A41,Analysis!A:A,0)),"") | G41: =IF(A41<>"",INDEX(Analysis!K:K,MATCH(A41,Analysis!A:A,0)),"")
A42: =IFERROR(INDEX(Analysis!A:A,SMALL(IF(Analysis!G:G="YES",ROW(Analysis!G:G)),9)),"") | B42: =IF(A42<>"",INDEX(Analysis!B:B,MATCH(A42,Analysis!A:A,0)),"") | C42: =IF(A42<>"",INDEX(Analysis!C:C,MATCH(A42,Analysis!A:A,0)),"") | D42: =IF(A42<>"",INDEX(Analysis!F:F,MATCH(A42,Analysis!A:A,0)),"") | E42: =IF(A42<>"",INDEX(Analysis!H:H,MATCH(A42,Analysis!A:A,0)),"") | F42: =IF(A42<>"",INDEX(Analysis!I:I,MATCH(A42,Analysis!A:A,0)),"") | G42: =IF(A42<>"",INDEX(Analysis!K:K,MATCH(A42,Analysis!A:A,0)),"")
A43: =IFERROR(INDEX(Analysis!A:A,SMALL(IF(Analysis!G:G="YES",ROW(Analysis!G:G)),10)),"") | B43: =IF(A43<>"",INDEX(Analysis!B:B,MATCH(A43,Analysis!A:A,0)),"") | C43: =IF(A43<>"",INDEX(Analysis!C:C,MATCH(A43,Analysis!A:A,0)),"") | D43: =IF(A43<>"",INDEX(Analysis!F:F,MATCH(A43,Analysis!A:A,0)),"") | E43: =IF(A43<>"",INDEX(Analysis!H:H,MATCH(A43,Analysis!A:A,0)),"") | F43: =IF(A43<>"",INDEX(Analysis!I:I,MATCH(A43,Analysis!A:A,0)),"") | G43: =IF(A43<>"",INDEX(Analysis!K:K,MATCH(A43,Analysis!A:A,0)),"")
A46: HOW TO USE:
A47: 1. Update inventory levels in the Inventory sheet as stock changes
...
